[2024-06-28 12:55:36 +0300] [7325] [INFO] Starting gunicorn 20.1.0
[2024-06-28 12:55:36 +0300] [7325] [INFO] Listening at: http://127.0.0.1:8000 (7325)
[2024-06-28 12:55:36 +0300] [7325] [INFO] Using worker: sync
[2024-06-28 12:55:36 +0300] [7326] [INFO] Booting worker with pid: 7326
[2024-06-28 12:55:36 +0300] [7327] [INFO] Booting worker with pid: 7327
[2024-06-28 12:55:36 +0300] [7328] [INFO] Booting worker with pid: 7328
[2024-06-28 12:55:49 +0300] [7325] [INFO] Handling signal: int
[2024-06-28 12:55:49 +0300] [7328] [INFO] Worker exiting (pid: 7328)
[2024-06-28 12:55:49 +0300] [7326] [INFO] Worker exiting (pid: 7326)
[2024-06-28 12:55:49 +0300] [7327] [INFO] Worker exiting (pid: 7327)
[2024-06-28 12:55:49 +0300] [7325] [INFO] Shutting down: Master
[2024-06-28 12:58:58 +0300] [7475] [INFO] Starting gunicorn 20.1.0
[2024-06-28 12:58:58 +0300] [7475] [INFO] Listening at: http://127.0.0.1:8000 (7475)
[2024-06-28 12:58:58 +0300] [7475] [INFO] Using worker: sync
[2024-06-28 12:58:58 +0300] [7476] [INFO] Booting worker with pid: 7476
[2024-06-28 12:58:58 +0300] [7476] [INFO] Worker exiting (pid: 7476)
[2024-06-28 12:58:58 +0300] [7475] [INFO] Shutting down: Master
[2024-06-28 12:58:58 +0300] [7475] [INFO] Reason: App failed to load.
[2024-06-28 12:59:08 +0300] [7481] [INFO] Starting gunicorn 20.1.0
[2024-06-28 12:59:08 +0300] [7481] [INFO] Listening at: http://127.0.0.1:8000 (7481)
[2024-06-28 12:59:08 +0300] [7481] [INFO] Using worker: sync
[2024-06-28 12:59:08 +0300] [7482] [INFO] Booting worker with pid: 7482
[2024-06-28 12:59:09 +0300] [7483] [INFO] Booting worker with pid: 7483
[2024-06-28 12:59:09 +0300] [7484] [INFO] Booting worker with pid: 7484
[2024-06-28 12:59:25 +0300] [7481] [INFO] Handling signal: int
[2024-06-28 12:59:25 +0300] [7484] [INFO] Worker exiting (pid: 7484)
[2024-06-28 12:59:25 +0300] [7483] [INFO] Worker exiting (pid: 7483)
[2024-06-28 12:59:25 +0300] [7482] [INFO] Worker exiting (pid: 7482)
[2024-06-28 12:59:25 +0300] [7481] [INFO] Shutting down: Master
[2024-06-28 13:01:17 +0300] [7532] [INFO] Starting gunicorn 20.1.0
[2024-06-28 13:01:17 +0300] [7532] [INFO] Listening at: http://127.0.0.1:8000 (7532)
[2024-06-28 13:01:17 +0300] [7532] [INFO] Using worker: sync
[2024-06-28 13:01:17 +0300] [7533] [INFO] Booting worker with pid: 7533
[2024-06-28 13:01:17 +0300] [7534] [INFO] Booting worker with pid: 7534
[2024-06-28 13:01:17 +0300] [7535] [INFO] Booting worker with pid: 7535
[2024-06-28 13:01:27 +0300] [7532] [INFO] Handling signal: int
[2024-06-28 13:01:27 +0300] [7534] [INFO] Worker exiting (pid: 7534)
[2024-06-28 13:01:27 +0300] [7535] [INFO] Worker exiting (pid: 7535)
[2024-06-28 13:01:27 +0300] [7533] [INFO] Worker exiting (pid: 7533)
[2024-06-28 13:01:27 +0300] [7532] [INFO] Shutting down: Master
[2024-06-28 13:09:40 +0300] [7803] [INFO] Starting gunicorn 20.1.0
[2024-06-28 13:09:40 +0300] [7803] [INFO] Listening at: http://0.0.0.0:8080 (7803)
[2024-06-28 13:09:40 +0300] [7803] [INFO] Using worker: sync
[2024-06-28 13:09:40 +0300] [7804] [INFO] Booting worker with pid: 7804
[2024-06-28 13:09:40 +0300] [7805] [INFO] Booting worker with pid: 7805
[2024-06-28 13:09:40 +0300] [7805] [ERROR] Exception in worker process
Traceback (most recent call last):
  File "/usr/lib/python3/dist-packages/gunicorn/arbiter.py", line 589, in spawn_worker
    worker.init_process()
  File "/usr/lib/python3/dist-packages/gunicorn/workers/base.py", line 134, in init_process
    self.load_wsgi()
  File "/usr/lib/python3/dist-packages/gunicorn/workers/base.py", line 146, in load_wsgi
    self.wsgi = self.app.wsgi()
                ^^^^^^^^^^^^^^^
  File "/usr/lib/python3/dist-packages/gunicorn/app/base.py", line 67, in wsgi
    self.callable = self.load()
                    ^^^^^^^^^^^
  File "/usr/lib/python3/dist-packages/gunicorn/app/wsgiapp.py", line 58, in load
    return self.load_wsgiapp()
           ^^^^^^^^^^^^^^^^^^^
  File "/usr/lib/python3/dist-packages/gunicorn/app/wsgiapp.py", line 48, in load_wsgiapp
    return util.import_app(self.app_uri)
           ^^^^^^^^^^^^^^^^^^^^^^^^^^^^^
  File "/usr/lib/python3/dist-packages/gunicorn/util.py", line 384, in import_app
    mod = importlib.import_module(module)
          ^^^^^^^^^^^^^^^^^^^^^^^^^^^^^^^
  File "/usr/lib/python3.12/importlib/__init__.py", line 90, in import_module
    return _bootstrap._gcd_import(name[level:], package, level)
           ^^^^^^^^^^^^^^^^^^^^^^^^^^^^^^^^^^^^^^^^^^^^^^^^^^^^
  File "<frozen importlib._bootstrap>", line 1387, in _gcd_import
  File "<frozen importlib._bootstrap>", line 1360, in _find_and_load
  File "<frozen importlib._bootstrap>", line 1310, in _find_and_load_unlocked
  File "<frozen importlib._bootstrap>", line 488, in _call_with_frames_removed
  File "<frozen importlib._bootstrap>", line 1387, in _gcd_import
  File "<frozen importlib._bootstrap>", line 1360, in _find_and_load
  File "<frozen importlib._bootstrap>", line 1324, in _find_and_load_unlocked
ModuleNotFoundError: No module named 'web-app'
[2024-06-28 13:09:40 +0300] [7804] [ERROR] Exception in worker process
Traceback (most recent call last):
  File "/usr/lib/python3/dist-packages/gunicorn/arbiter.py", line 589, in spawn_worker
    worker.init_process()
  File "/usr/lib/python3/dist-packages/gunicorn/workers/base.py", line 134, in init_process
    self.load_wsgi()
  File "/usr/lib/python3/dist-packages/gunicorn/workers/base.py", line 146, in load_wsgi
    self.wsgi = self.app.wsgi()
                ^^^^^^^^^^^^^^^
  File "/usr/lib/python3/dist-packages/gunicorn/app/base.py", line 67, in wsgi
    self.callable = self.load()
                    ^^^^^^^^^^^
  File "/usr/lib/python3/dist-packages/gunicorn/app/wsgiapp.py", line 58, in load
    return self.load_wsgiapp()
           ^^^^^^^^^^^^^^^^^^^
  File "/usr/lib/python3/dist-packages/gunicorn/app/wsgiapp.py", line 48, in load_wsgiapp
    return util.import_app(self.app_uri)
           ^^^^^^^^^^^^^^^^^^^^^^^^^^^^^
  File "/usr/lib/python3/dist-packages/gunicorn/util.py", line 384, in import_app
    mod = importlib.import_module(module)
          ^^^^^^^^^^^^^^^^^^^^^^^^^^^^^^^
  File "/usr/lib/python3.12/importlib/__init__.py", line 90, in import_module
    return _bootstrap._gcd_import(name[level:], package, level)
           ^^^^^^^^^^^^^^^^^^^^^^^^^^^^^^^^^^^^^^^^^^^^^^^^^^^^
  File "<frozen importlib._bootstrap>", line 1387, in _gcd_import
  File "<frozen importlib._bootstrap>", line 1360, in _find_and_load
  File "<frozen importlib._bootstrap>", line 1310, in _find_and_load_unlocked
  File "<frozen importlib._bootstrap>", line 488, in _call_with_frames_removed
  File "<frozen importlib._bootstrap>", line 1387, in _gcd_import
  File "<frozen importlib._bootstrap>", line 1360, in _find_and_load
  File "<frozen importlib._bootstrap>", line 1324, in _find_and_load_unlocked
ModuleNotFoundError: No module named 'web-app'
[2024-06-28 13:09:40 +0300] [7804] [INFO] Worker exiting (pid: 7804)
[2024-06-28 13:09:40 +0300] [7805] [INFO] Worker exiting (pid: 7805)
[2024-06-28 13:09:40 +0300] [7806] [INFO] Booting worker with pid: 7806
[2024-06-28 13:09:40 +0300] [7806] [ERROR] Exception in worker process
Traceback (most recent call last):
  File "/usr/lib/python3/dist-packages/gunicorn/arbiter.py", line 589, in spawn_worker
    worker.init_process()
  File "/usr/lib/python3/dist-packages/gunicorn/workers/base.py", line 134, in init_process
    self.load_wsgi()
  File "/usr/lib/python3/dist-packages/gunicorn/workers/base.py", line 146, in load_wsgi
    self.wsgi = self.app.wsgi()
                ^^^^^^^^^^^^^^^
  File "/usr/lib/python3/dist-packages/gunicorn/app/base.py", line 67, in wsgi
    self.callable = self.load()
                    ^^^^^^^^^^^
  File "/usr/lib/python3/dist-packages/gunicorn/app/wsgiapp.py", line 58, in load
    return self.load_wsgiapp()
           ^^^^^^^^^^^^^^^^^^^
  File "/usr/lib/python3/dist-packages/gunicorn/app/wsgiapp.py", line 48, in load_wsgiapp
    return util.import_app(self.app_uri)
           ^^^^^^^^^^^^^^^^^^^^^^^^^^^^^
  File "/usr/lib/python3/dist-packages/gunicorn/util.py", line 384, in import_app
    mod = importlib.import_module(module)
          ^^^^^^^^^^^^^^^^^^^^^^^^^^^^^^^
  File "/usr/lib/python3.12/importlib/__init__.py", line 90, in import_module
    return _bootstrap._gcd_import(name[level:], package, level)
           ^^^^^^^^^^^^^^^^^^^^^^^^^^^^^^^^^^^^^^^^^^^^^^^^^^^^
  File "<frozen importlib._bootstrap>", line 1387, in _gcd_import
  File "<frozen importlib._bootstrap>", line 1360, in _find_and_load
  File "<frozen importlib._bootstrap>", line 1310, in _find_and_load_unlocked
  File "<frozen importlib._bootstrap>", line 488, in _call_with_frames_removed
  File "<frozen importlib._bootstrap>", line 1387, in _gcd_import
  File "<frozen importlib._bootstrap>", line 1360, in _find_and_load
  File "<frozen importlib._bootstrap>", line 1324, in _find_and_load_unlocked
ModuleNotFoundError: No module named 'web-app'
[2024-06-28 13:09:40 +0300] [7806] [INFO] Worker exiting (pid: 7806)
[2024-06-28 13:09:40 +0300] [7803] [WARNING] Worker with pid 7804 was terminated due to signal 15
[2024-06-28 13:09:40 +0300] [7803] [WARNING] Worker with pid 7806 was terminated due to signal 15
[2024-06-28 13:09:41 +0300] [7803] [INFO] Shutting down: Master
[2024-06-28 13:09:41 +0300] [7803] [INFO] Reason: Worker failed to boot.
[2024-06-28 13:10:22 +0300] [7871] [INFO] Starting gunicorn 20.1.0
[2024-06-28 13:10:22 +0300] [7871] [INFO] Listening at: http://0.0.0.0:8080 (7871)
[2024-06-28 13:10:22 +0300] [7871] [INFO] Using worker: sync
[2024-06-28 13:10:22 +0300] [7872] [INFO] Booting worker with pid: 7872
[2024-06-28 13:10:22 +0300] [7872] [ERROR] Exception in worker process
Traceback (most recent call last):
  File "/usr/lib/python3/dist-packages/gunicorn/arbiter.py", line 589, in spawn_worker
    worker.init_process()
  File "/usr/lib/python3/dist-packages/gunicorn/workers/base.py", line 134, in init_process
    self.load_wsgi()
  File "/usr/lib/python3/dist-packages/gunicorn/workers/base.py", line 146, in load_wsgi
    self.wsgi = self.app.wsgi()
                ^^^^^^^^^^^^^^^
  File "/usr/lib/python3/dist-packages/gunicorn/app/base.py", line 67, in wsgi
    self.callable = self.load()
                    ^^^^^^^^^^^
  File "/usr/lib/python3/dist-packages/gunicorn/app/wsgiapp.py", line 58, in load
    return self.load_wsgiapp()
           ^^^^^^^^^^^^^^^^^^^
  File "/usr/lib/python3/dist-packages/gunicorn/app/wsgiapp.py", line 48, in load_wsgiapp
    return util.import_app(self.app_uri)
           ^^^^^^^^^^^^^^^^^^^^^^^^^^^^^
  File "/usr/lib/python3/dist-packages/gunicorn/util.py", line 384, in import_app
    mod = importlib.import_module(module)
          ^^^^^^^^^^^^^^^^^^^^^^^^^^^^^^^
  File "/usr/lib/python3.12/importlib/__init__.py", line 90, in import_module
    return _bootstrap._gcd_import(name[level:], package, level)
           ^^^^^^^^^^^^^^^^^^^^^^^^^^^^^^^^^^^^^^^^^^^^^^^^^^^^
  File "<frozen importlib._bootstrap>", line 1387, in _gcd_import
  File "<frozen importlib._bootstrap>", line 1360, in _find_and_load
  File "<frozen importlib._bootstrap>", line 1310, in _find_and_load_unlocked
  File "<frozen importlib._bootstrap>", line 488, in _call_with_frames_removed
  File "<frozen importlib._bootstrap>", line 1387, in _gcd_import
  File "<frozen importlib._bootstrap>", line 1360, in _find_and_load
  File "<frozen importlib._bootstrap>", line 1324, in _find_and_load_unlocked
ModuleNotFoundError: No module named 'web-app'
[2024-06-28 13:10:22 +0300] [7872] [INFO] Worker exiting (pid: 7872)
[2024-06-28 13:10:22 +0300] [7873] [INFO] Booting worker with pid: 7873
[2024-06-28 13:10:22 +0300] [7873] [ERROR] Exception in worker process
Traceback (most recent call last):
  File "/usr/lib/python3/dist-packages/gunicorn/arbiter.py", line 589, in spawn_worker
    worker.init_process()
  File "/usr/lib/python3/dist-packages/gunicorn/workers/base.py", line 134, in init_process
    self.load_wsgi()
  File "/usr/lib/python3/dist-packages/gunicorn/workers/base.py", line 146, in load_wsgi
    self.wsgi = self.app.wsgi()
                ^^^^^^^^^^^^^^^
  File "/usr/lib/python3/dist-packages/gunicorn/app/base.py", line 67, in wsgi
    self.callable = self.load()
                    ^^^^^^^^^^^
  File "/usr/lib/python3/dist-packages/gunicorn/app/wsgiapp.py", line 58, in load
    return self.load_wsgiapp()
           ^^^^^^^^^^^^^^^^^^^
  File "/usr/lib/python3/dist-packages/gunicorn/app/wsgiapp.py", line 48, in load_wsgiapp
    return util.import_app(self.app_uri)
           ^^^^^^^^^^^^^^^^^^^^^^^^^^^^^
  File "/usr/lib/python3/dist-packages/gunicorn/util.py", line 384, in import_app
    mod = importlib.import_module(module)
          ^^^^^^^^^^^^^^^^^^^^^^^^^^^^^^^
  File "/usr/lib/python3.12/importlib/__init__.py", line 90, in import_module
    return _bootstrap._gcd_import(name[level:], package, level)
           ^^^^^^^^^^^^^^^^^^^^^^^^^^^^^^^^^^^^^^^^^^^^^^^^^^^^
  File "<frozen importlib._bootstrap>", line 1387, in _gcd_import
  File "<frozen importlib._bootstrap>", line 1360, in _find_and_load
  File "<frozen importlib._bootstrap>", line 1310, in _find_and_load_unlocked
  File "<frozen importlib._bootstrap>", line 488, in _call_with_frames_removed
  File "<frozen importlib._bootstrap>", line 1387, in _gcd_import
  File "<frozen importlib._bootstrap>", line 1360, in _find_and_load
  File "<frozen importlib._bootstrap>", line 1324, in _find_and_load_unlocked
ModuleNotFoundError: No module named 'web-app'
[2024-06-28 13:10:22 +0300] [7873] [INFO] Worker exiting (pid: 7873)
[2024-06-28 13:10:22 +0300] [7874] [INFO] Booting worker with pid: 7874
[2024-06-28 13:10:22 +0300] [7874] [ERROR] Exception in worker process
Traceback (most recent call last):
  File "/usr/lib/python3/dist-packages/gunicorn/arbiter.py", line 589, in spawn_worker
    worker.init_process()
  File "/usr/lib/python3/dist-packages/gunicorn/workers/base.py", line 134, in init_process
    self.load_wsgi()
  File "/usr/lib/python3/dist-packages/gunicorn/workers/base.py", line 146, in load_wsgi
    self.wsgi = self.app.wsgi()
                ^^^^^^^^^^^^^^^
  File "/usr/lib/python3/dist-packages/gunicorn/app/base.py", line 67, in wsgi
    self.callable = self.load()
                    ^^^^^^^^^^^
  File "/usr/lib/python3/dist-packages/gunicorn/app/wsgiapp.py", line 58, in load
    return self.load_wsgiapp()
           ^^^^^^^^^^^^^^^^^^^
  File "/usr/lib/python3/dist-packages/gunicorn/app/wsgiapp.py", line 48, in load_wsgiapp
    return util.import_app(self.app_uri)
           ^^^^^^^^^^^^^^^^^^^^^^^^^^^^^
  File "/usr/lib/python3/dist-packages/gunicorn/util.py", line 384, in import_app
    mod = importlib.import_module(module)
          ^^^^^^^^^^^^^^^^^^^^^^^^^^^^^^^
  File "/usr/lib/python3.12/importlib/__init__.py", line 90, in import_module
    return _bootstrap._gcd_import(name[level:], package, level)
           ^^^^^^^^^^^^^^^^^^^^^^^^^^^^^^^^^^^^^^^^^^^^^^^^^^^^
  File "<frozen importlib._bootstrap>", line 1387, in _gcd_import
  File "<frozen importlib._bootstrap>", line 1360, in _find_and_load
  File "<frozen importlib._bootstrap>", line 1310, in _find_and_load_unlocked
  File "<frozen importlib._bootstrap>", line 488, in _call_with_frames_removed
  File "<frozen importlib._bootstrap>", line 1387, in _gcd_import
  File "<frozen importlib._bootstrap>", line 1360, in _find_and_load
  File "<frozen importlib._bootstrap>", line 1324, in _find_and_load_unlocked
ModuleNotFoundError: No module named 'web-app'
[2024-06-28 13:10:22 +0300] [7874] [INFO] Worker exiting (pid: 7874)
[2024-06-28 13:10:22 +0300] [7871] [WARNING] Worker with pid 7873 was terminated due to signal 15
[2024-06-28 13:10:22 +0300] [7871] [WARNING] Worker with pid 7874 was terminated due to signal 15
[2024-06-28 13:10:22 +0300] [7871] [INFO] Shutting down: Master
[2024-06-28 13:10:22 +0300] [7871] [INFO] Reason: Worker failed to boot.
[2024-06-28 13:13:45 +0300] [7953] [INFO] Starting gunicorn 20.1.0
[2024-06-28 13:13:45 +0300] [7953] [INFO] Listening at: http://0.0.0.0:8080 (7953)
[2024-06-28 13:13:45 +0300] [7953] [INFO] Using worker: sync
[2024-06-28 13:13:45 +0300] [7954] [INFO] Booting worker with pid: 7954
[2024-06-28 13:13:45 +0300] [7954] [ERROR] Exception in worker process
Traceback (most recent call last):
  File "/usr/lib/python3/dist-packages/gunicorn/arbiter.py", line 589, in spawn_worker
    worker.init_process()
  File "/usr/lib/python3/dist-packages/gunicorn/workers/base.py", line 134, in init_process
    self.load_wsgi()
  File "/usr/lib/python3/dist-packages/gunicorn/workers/base.py", line 146, in load_wsgi
    self.wsgi = self.app.wsgi()
                ^^^^^^^^^^^^^^^
  File "/usr/lib/python3/dist-packages/gunicorn/app/base.py", line 67, in wsgi
    self.callable = self.load()
                    ^^^^^^^^^^^
  File "/usr/lib/python3/dist-packages/gunicorn/app/wsgiapp.py", line 58, in load
    return self.load_wsgiapp()
           ^^^^^^^^^^^^^^^^^^^
  File "/usr/lib/python3/dist-packages/gunicorn/app/wsgiapp.py", line 48, in load_wsgiapp
    return util.import_app(self.app_uri)
           ^^^^^^^^^^^^^^^^^^^^^^^^^^^^^
  File "/usr/lib/python3/dist-packages/gunicorn/util.py", line 384, in import_app
    mod = importlib.import_module(module)
          ^^^^^^^^^^^^^^^^^^^^^^^^^^^^^^^
  File "/usr/lib/python3.12/importlib/__init__.py", line 90, in import_module
    return _bootstrap._gcd_import(name[level:], package, level)
           ^^^^^^^^^^^^^^^^^^^^^^^^^^^^^^^^^^^^^^^^^^^^^^^^^^^^
  File "<frozen importlib._bootstrap>", line 1387, in _gcd_import
  File "<frozen importlib._bootstrap>", line 1360, in _find_and_load
  File "<frozen importlib._bootstrap>", line 1310, in _find_and_load_unlocked
  File "<frozen importlib._bootstrap>", line 488, in _call_with_frames_removed
  File "<frozen importlib._bootstrap>", line 1387, in _gcd_import
  File "<frozen importlib._bootstrap>", line 1360, in _find_and_load
  File "<frozen importlib._bootstrap>", line 1324, in _find_and_load_unlocked
ModuleNotFoundError: No module named 'web-app'
[2024-06-28 13:13:45 +0300] [7954] [INFO] Worker exiting (pid: 7954)
[2024-06-28 13:13:45 +0300] [7955] [INFO] Booting worker with pid: 7955
[2024-06-28 13:13:45 +0300] [7955] [ERROR] Exception in worker process
Traceback (most recent call last):
  File "/usr/lib/python3/dist-packages/gunicorn/arbiter.py", line 589, in spawn_worker
    worker.init_process()
  File "/usr/lib/python3/dist-packages/gunicorn/workers/base.py", line 134, in init_process
    self.load_wsgi()
  File "/usr/lib/python3/dist-packages/gunicorn/workers/base.py", line 146, in load_wsgi
    self.wsgi = self.app.wsgi()
                ^^^^^^^^^^^^^^^
  File "/usr/lib/python3/dist-packages/gunicorn/app/base.py", line 67, in wsgi
    self.callable = self.load()
                    ^^^^^^^^^^^
  File "/usr/lib/python3/dist-packages/gunicorn/app/wsgiapp.py", line 58, in load
    return self.load_wsgiapp()
           ^^^^^^^^^^^^^^^^^^^
  File "/usr/lib/python3/dist-packages/gunicorn/app/wsgiapp.py", line 48, in load_wsgiapp
    return util.import_app(self.app_uri)
           ^^^^^^^^^^^^^^^^^^^^^^^^^^^^^
  File "/usr/lib/python3/dist-packages/gunicorn/util.py", line 384, in import_app
    mod = importlib.import_module(module)
          ^^^^^^^^^^^^^^^^^^^^^^^^^^^^^^^
  File "/usr/lib/python3.12/importlib/__init__.py", line 90, in import_module
    return _bootstrap._gcd_import(name[level:], package, level)
           ^^^^^^^^^^^^^^^^^^^^^^^^^^^^^^^^^^^^^^^^^^^^^^^^^^^^
  File "<frozen importlib._bootstrap>", line 1387, in _gcd_import
  File "<frozen importlib._bootstrap>", line 1360, in _find_and_load
  File "<frozen importlib._bootstrap>", line 1310, in _find_and_load_unlocked
  File "<frozen importlib._bootstrap>", line 488, in _call_with_frames_removed
  File "<frozen importlib._bootstrap>", line 1387, in _gcd_import
  File "<frozen importlib._bootstrap>", line 1360, in _find_and_load
  File "<frozen importlib._bootstrap>", line 1324, in _find_and_load_unlocked
ModuleNotFoundError: No module named 'web-app'
[2024-06-28 13:13:45 +0300] [7955] [INFO] Worker exiting (pid: 7955)
[2024-06-28 13:13:45 +0300] [7956] [INFO] Booting worker with pid: 7956
[2024-06-28 13:13:45 +0300] [7953] [WARNING] Worker with pid 7955 was terminated due to signal 15
[2024-06-28 13:13:45 +0300] [7956] [ERROR] Exception in worker process
Traceback (most recent call last):
  File "/usr/lib/python3/dist-packages/gunicorn/arbiter.py", line 589, in spawn_worker
    worker.init_process()
  File "/usr/lib/python3/dist-packages/gunicorn/workers/base.py", line 134, in init_process
    self.load_wsgi()
  File "/usr/lib/python3/dist-packages/gunicorn/workers/base.py", line 146, in load_wsgi
    self.wsgi = self.app.wsgi()
                ^^^^^^^^^^^^^^^
  File "/usr/lib/python3/dist-packages/gunicorn/app/base.py", line 67, in wsgi
    self.callable = self.load()
                    ^^^^^^^^^^^
  File "/usr/lib/python3/dist-packages/gunicorn/app/wsgiapp.py", line 58, in load
    return self.load_wsgiapp()
           ^^^^^^^^^^^^^^^^^^^
  File "/usr/lib/python3/dist-packages/gunicorn/app/wsgiapp.py", line 48, in load_wsgiapp
    return util.import_app(self.app_uri)
           ^^^^^^^^^^^^^^^^^^^^^^^^^^^^^
  File "/usr/lib/python3/dist-packages/gunicorn/util.py", line 384, in import_app
    mod = importlib.import_module(module)
          ^^^^^^^^^^^^^^^^^^^^^^^^^^^^^^^
  File "/usr/lib/python3.12/importlib/__init__.py", line 90, in import_module
    return _bootstrap._gcd_import(name[level:], package, level)
           ^^^^^^^^^^^^^^^^^^^^^^^^^^^^^^^^^^^^^^^^^^^^^^^^^^^^
  File "<frozen importlib._bootstrap>", line 1387, in _gcd_import
  File "<frozen importlib._bootstrap>", line 1360, in _find_and_load
  File "<frozen importlib._bootstrap>", line 1310, in _find_and_load_unlocked
  File "<frozen importlib._bootstrap>", line 488, in _call_with_frames_removed
  File "<frozen importlib._bootstrap>", line 1387, in _gcd_import
  File "<frozen importlib._bootstrap>", line 1360, in _find_and_load
  File "<frozen importlib._bootstrap>", line 1324, in _find_and_load_unlocked
ModuleNotFoundError: No module named 'web-app'
[2024-06-28 13:13:45 +0300] [7956] [INFO] Worker exiting (pid: 7956)
[2024-06-28 13:15:14 +0300] [8010] [INFO] Starting gunicorn 20.1.0
[2024-06-28 13:15:14 +0300] [8010] [INFO] Listening at: http://0.0.0.0:8080 (8010)
[2024-06-28 13:15:14 +0300] [8010] [INFO] Using worker: sync
[2024-06-28 13:15:14 +0300] [8012] [INFO] Booting worker with pid: 8012
[2024-06-28 13:15:14 +0300] [8012] [ERROR] Exception in worker process
Traceback (most recent call last):
  File "/usr/lib/python3/dist-packages/gunicorn/arbiter.py", line 589, in spawn_worker
    worker.init_process()
  File "/usr/lib/python3/dist-packages/gunicorn/workers/base.py", line 134, in init_process
    self.load_wsgi()
  File "/usr/lib/python3/dist-packages/gunicorn/workers/base.py", line 146, in load_wsgi
    self.wsgi = self.app.wsgi()
                ^^^^^^^^^^^^^^^
  File "/usr/lib/python3/dist-packages/gunicorn/app/base.py", line 67, in wsgi
    self.callable = self.load()
                    ^^^^^^^^^^^
  File "/usr/lib/python3/dist-packages/gunicorn/app/wsgiapp.py", line 58, in load
    return self.load_wsgiapp()
           ^^^^^^^^^^^^^^^^^^^
  File "/usr/lib/python3/dist-packages/gunicorn/app/wsgiapp.py", line 48, in load_wsgiapp
    return util.import_app(self.app_uri)
           ^^^^^^^^^^^^^^^^^^^^^^^^^^^^^
  File "/usr/lib/python3/dist-packages/gunicorn/util.py", line 384, in import_app
    mod = importlib.import_module(module)
          ^^^^^^^^^^^^^^^^^^^^^^^^^^^^^^^
  File "/usr/lib/python3.12/importlib/__init__.py", line 90, in import_module
    return _bootstrap._gcd_import(name[level:], package, level)
           ^^^^^^^^^^^^^^^^^^^^^^^^^^^^^^^^^^^^^^^^^^^^^^^^^^^^
  File "<frozen importlib._bootstrap>", line 1387, in _gcd_import
  File "<frozen importlib._bootstrap>", line 1360, in _find_and_load
  File "<frozen importlib._bootstrap>", line 1310, in _find_and_load_unlocked
  File "<frozen importlib._bootstrap>", line 488, in _call_with_frames_removed
  File "<frozen importlib._bootstrap>", line 1387, in _gcd_import
  File "<frozen importlib._bootstrap>", line 1360, in _find_and_load
  File "<frozen importlib._bootstrap>", line 1324, in _find_and_load_unlocked
ModuleNotFoundError: No module named 'web-app'
[2024-06-28 13:15:14 +0300] [8012] [INFO] Worker exiting (pid: 8012)
[2024-06-28 13:15:14 +0300] [8013] [INFO] Booting worker with pid: 8013
[2024-06-28 13:15:14 +0300] [8013] [ERROR] Exception in worker process
Traceback (most recent call last):
  File "/usr/lib/python3/dist-packages/gunicorn/arbiter.py", line 589, in spawn_worker
    worker.init_process()
  File "/usr/lib/python3/dist-packages/gunicorn/workers/base.py", line 134, in init_process
    self.load_wsgi()
  File "/usr/lib/python3/dist-packages/gunicorn/workers/base.py", line 146, in load_wsgi
    self.wsgi = self.app.wsgi()
                ^^^^^^^^^^^^^^^
  File "/usr/lib/python3/dist-packages/gunicorn/app/base.py", line 67, in wsgi
    self.callable = self.load()
                    ^^^^^^^^^^^
  File "/usr/lib/python3/dist-packages/gunicorn/app/wsgiapp.py", line 58, in load
    return self.load_wsgiapp()
           ^^^^^^^^^^^^^^^^^^^
  File "/usr/lib/python3/dist-packages/gunicorn/app/wsgiapp.py", line 48, in load_wsgiapp
    return util.import_app(self.app_uri)
           ^^^^^^^^^^^^^^^^^^^^^^^^^^^^^
  File "/usr/lib/python3/dist-packages/gunicorn/util.py", line 384, in import_app
    mod = importlib.import_module(module)
          ^^^^^^^^^^^^^^^^^^^^^^^^^^^^^^^
  File "/usr/lib/python3.12/importlib/__init__.py", line 90, in import_module
    return _bootstrap._gcd_import(name[level:], package, level)
           ^^^^^^^^^^^^^^^^^^^^^^^^^^^^^^^^^^^^^^^^^^^^^^^^^^^^
  File "<frozen importlib._bootstrap>", line 1387, in _gcd_import
  File "<frozen importlib._bootstrap>", line 1360, in _find_and_load
  File "<frozen importlib._bootstrap>", line 1310, in _find_and_load_unlocked
  File "<frozen importlib._bootstrap>", line 488, in _call_with_frames_removed
  File "<frozen importlib._bootstrap>", line 1387, in _gcd_import
  File "<frozen importlib._bootstrap>", line 1360, in _find_and_load
  File "<frozen importlib._bootstrap>", line 1324, in _find_and_load_unlocked
ModuleNotFoundError: No module named 'web-app'
[2024-06-28 13:15:14 +0300] [8013] [INFO] Worker exiting (pid: 8013)
[2024-06-28 13:15:14 +0300] [8010] [WARNING] Worker with pid 8013 was terminated due to signal 15
[2024-06-28 13:15:14 +0300] [8010] [INFO] Shutting down: Master
[2024-06-28 13:15:14 +0300] [8010] [INFO] Reason: Worker failed to boot.
[2024-06-28 13:18:40 +0300] [2562] [INFO] Starting gunicorn 20.1.0
[2024-06-28 13:18:40 +0300] [2562] [INFO] Listening at: http://127.0.0.1:8000 (2562)
[2024-06-28 13:18:40 +0300] [2562] [INFO] Using worker: sync
[2024-06-28 13:18:40 +0300] [2710] [INFO] Booting worker with pid: 2710
[2024-06-28 13:18:40 +0300] [2711] [INFO] Booting worker with pid: 2711
[2024-06-28 13:18:40 +0300] [2712] [INFO] Booting worker with pid: 2712
[2024-06-28 13:19:03 +0300] [2712] [ERROR] Exception in worker process
Traceback (most recent call last):
  File "/home/hk/.local/lib/python3.12/site-packages/sqlalchemy/engine/base.py", line 146, in __init__
    self._dbapi_connection = engine.raw_connection()
                             ^^^^^^^^^^^^^^^^^^^^^^^
  File "/home/hk/.local/lib/python3.12/site-packages/sqlalchemy/engine/base.py", line 3300, in raw_connection
    return self.pool.connect()
           ^^^^^^^^^^^^^^^^^^^
  File "/home/hk/.local/lib/python3.12/site-packages/sqlalchemy/pool/base.py", line 449, in connect
    return _ConnectionFairy._checkout(self)
           ^^^^^^^^^^^^^^^^^^^^^^^^^^^^^^^^
  File "/home/hk/.local/lib/python3.12/site-packages/sqlalchemy/pool/base.py", line 1263, in _checkout
    fairy = _ConnectionRecord.checkout(pool)
            ^^^^^^^^^^^^^^^^^^^^^^^^^^^^^^^^
  File "/home/hk/.local/lib/python3.12/site-packages/sqlalchemy/pool/base.py", line 712, in checkout
    rec = pool._do_get()
          ^^^^^^^^^^^^^^
  File "/home/hk/.local/lib/python3.12/site-packages/sqlalchemy/pool/impl.py", line 179, in _do_get
    with util.safe_reraise():
  File "/home/hk/.local/lib/python3.12/site-packages/sqlalchemy/util/langhelpers.py", line 146, in __exit__
    raise exc_value.with_traceback(exc_tb)
  File "/home/hk/.local/lib/python3.12/site-packages/sqlalchemy/pool/impl.py", line 177, in _do_get
    return self._create_connection()
           ^^^^^^^^^^^^^^^^^^^^^^^^^
  File "/home/hk/.local/lib/python3.12/site-packages/sqlalchemy/pool/base.py", line 390, in _create_connection
    return _ConnectionRecord(self)
           ^^^^^^^^^^^^^^^^^^^^^^^
  File "/home/hk/.local/lib/python3.12/site-packages/sqlalchemy/pool/base.py", line 674, in __init__
    self.__connect()
  File "/home/hk/.local/lib/python3.12/site-packages/sqlalchemy/pool/base.py", line 900, in __connect
    with util.safe_reraise():
  File "/home/hk/.local/lib/python3.12/site-packages/sqlalchemy/util/langhelpers.py", line 146, in __exit__
    raise exc_value.with_traceback(exc_tb)
  File "/home/hk/.local/lib/python3.12/site-packages/sqlalchemy/pool/base.py", line 896, in __connect
    self.dbapi_connection = connection = pool._invoke_creator(self)
                                         ^^^^^^^^^^^^^^^^^^^^^^^^^^
  File "/home/hk/.local/lib/python3.12/site-packages/sqlalchemy/engine/create.py", line 643, in connect
    return dialect.connect(*cargs, **cparams)
           ^^^^^^^^^^^^^^^^^^^^^^^^^^^^^^^^^^
  File "/home/hk/.local/lib/python3.12/site-packages/sqlalchemy/engine/default.py", line 620, in connect
    return self.loaded_dbapi.connect(*cargs, **cparams)
           ^^^^^^^^^^^^^^^^^^^^^^^^^^^^^^^^^^^^^^^^^^^^
  File "/usr/local/lib/python3.12/dist-packages/MySQLdb/__init__.py", line 121, in Connect
    return Connection(*args, **kwargs)
           ^^^^^^^^^^^^^^^^^^^^^^^^^^^
  File "/usr/local/lib/python3.12/dist-packages/MySQLdb/connections.py", line 195, in __init__
    super().__init__(*args, **kwargs2)
MySQLdb.OperationalError: (2002, "Can't connect to local MySQL server through socket '/var/run/mysqld/mysqld.sock' (2)")

The above exception was the direct cause of the following exception:

Traceback (most recent call last):
  File "/usr/lib/python3/dist-packages/gunicorn/arbiter.py", line 589, in spawn_worker
    worker.init_process()
  File "/usr/lib/python3/dist-packages/gunicorn/workers/base.py", line 134, in init_process
    self.load_wsgi()
  File "/usr/lib/python3/dist-packages/gunicorn/workers/base.py", line 146, in load_wsgi
    self.wsgi = self.app.wsgi()
                ^^^^^^^^^^^^^^^
  File "/usr/lib/python3/dist-packages/gunicorn/app/base.py", line 67, in wsgi
    self.callable = self.load()
                    ^^^^^^^^^^^
  File "/usr/lib/python3/dist-packages/gunicorn/app/wsgiapp.py", line 58, in load
    return self.load_wsgiapp()
           ^^^^^^^^^^^^^^^^^^^
  File "/usr/lib/python3/dist-packages/gunicorn/app/wsgiapp.py", line 48, in load_wsgiapp
    return util.import_app(self.app_uri)
           ^^^^^^^^^^^^^^^^^^^^^^^^^^^^^
  File "/usr/lib/python3/dist-packages/gunicorn/util.py", line 384, in import_app
    mod = importlib.import_module(module)
          ^^^^^^^^^^^^^^^^^^^^^^^^^^^^^^^
  File "/usr/lib/python3.12/importlib/__init__.py", line 90, in import_module
    return _bootstrap._gcd_import(name[level:], package, level)
           ^^^^^^^^^^^^^^^^^^^^^^^^^^^^^^^^^^^^^^^^^^^^^^^^^^^^
  File "<frozen importlib._bootstrap>", line 1387, in _gcd_import
  File "<frozen importlib._bootstrap>", line 1360, in _find_and_load
  File "<frozen importlib._bootstrap>", line 1331, in _find_and_load_unlocked
  File "<frozen importlib._bootstrap>", line 935, in _load_unlocked
  File "<frozen importlib._bootstrap_external>", line 995, in exec_module
  File "<frozen importlib._bootstrap>", line 488, in _call_with_frames_removed
  File "/home/hk/grocree/webapp/v1/app.py", line 3, in <module>
    from models import Customer, Order, Orderline, Grocery
  File "/home/hk/grocree/models/__init__.py", line 6, in <module>
    storage.reload()
  File "/home/hk/grocree/models/storage/db_storage.py", line 48, in reload
    base.metadata.create_all(self.__engine)
  File "/home/hk/.local/lib/python3.12/site-packages/sqlalchemy/sql/schema.py", line 5857, in create_all
    bind._run_ddl_visitor(
  File "/home/hk/.local/lib/python3.12/site-packages/sqlalchemy/engine/base.py", line 3250, in _run_ddl_visitor
    with self.begin() as conn:
  File "/usr/lib/python3.12/contextlib.py", line 137, in __enter__
    return next(self.gen)
           ^^^^^^^^^^^^^^
  File "/home/hk/.local/lib/python3.12/site-packages/sqlalchemy/engine/base.py", line 3240, in begin
    with self.connect() as conn:
         ^^^^^^^^^^^^^^
  File "/home/hk/.local/lib/python3.12/site-packages/sqlalchemy/engine/base.py", line 3276, in connect
    return self._connection_cls(self)
           ^^^^^^^^^^^^^^^^^^^^^^^^^^
  File "/home/hk/.local/lib/python3.12/site-packages/sqlalchemy/engine/base.py", line 148, in __init__
    Connection._handle_dbapi_exception_noconnection(
  File "/home/hk/.local/lib/python3.12/site-packages/sqlalchemy/engine/base.py", line 2440, in _handle_dbapi_exception_noconnection
    raise sqlalchemy_exception.with_traceback(exc_info[2]) from e
  File "/home/hk/.local/lib/python3.12/site-packages/sqlalchemy/engine/base.py", line 146, in __init__
    self._dbapi_connection = engine.raw_connection()
                             ^^^^^^^^^^^^^^^^^^^^^^^
  File "/home/hk/.local/lib/python3.12/site-packages/sqlalchemy/engine/base.py", line 3300, in raw_connection
    return self.pool.connect()
           ^^^^^^^^^^^^^^^^^^^
  File "/home/hk/.local/lib/python3.12/site-packages/sqlalchemy/pool/base.py", line 449, in connect
    return _ConnectionFairy._checkout(self)
           ^^^^^^^^^^^^^^^^^^^^^^^^^^^^^^^^
  File "/home/hk/.local/lib/python3.12/site-packages/sqlalchemy/pool/base.py", line 1263, in _checkout
    fairy = _ConnectionRecord.checkout(pool)
            ^^^^^^^^^^^^^^^^^^^^^^^^^^^^^^^^
  File "/home/hk/.local/lib/python3.12/site-packages/sqlalchemy/pool/base.py", line 712, in checkout
    rec = pool._do_get()
          ^^^^^^^^^^^^^^
  File "/home/hk/.local/lib/python3.12/site-packages/sqlalchemy/pool/impl.py", line 179, in _do_get
    with util.safe_reraise():
  File "/home/hk/.local/lib/python3.12/site-packages/sqlalchemy/util/langhelpers.py", line 146, in __exit__
    raise exc_value.with_traceback(exc_tb)
  File "/home/hk/.local/lib/python3.12/site-packages/sqlalchemy/pool/impl.py", line 177, in _do_get
    return self._create_connection()
           ^^^^^^^^^^^^^^^^^^^^^^^^^
  File "/home/hk/.local/lib/python3.12/site-packages/sqlalchemy/pool/base.py", line 390, in _create_connection
    return _ConnectionRecord(self)
           ^^^^^^^^^^^^^^^^^^^^^^^
  File "/home/hk/.local/lib/python3.12/site-packages/sqlalchemy/pool/base.py", line 674, in __init__
    self.__connect()
  File "/home/hk/.local/lib/python3.12/site-packages/sqlalchemy/pool/base.py", line 900, in __connect
    with util.safe_reraise():
  File "/home/hk/.local/lib/python3.12/site-packages/sqlalchemy/util/langhelpers.py", line 146, in __exit__
    raise exc_value.with_traceback(exc_tb)
  File "/home/hk/.local/lib/python3.12/site-packages/sqlalchemy/pool/base.py", line 896, in __connect
    self.dbapi_connection = connection = pool._invoke_creator(self)
                                         ^^^^^^^^^^^^^^^^^^^^^^^^^^
  File "/home/hk/.local/lib/python3.12/site-packages/sqlalchemy/engine/create.py", line 643, in connect
    return dialect.connect(*cargs, **cparams)
           ^^^^^^^^^^^^^^^^^^^^^^^^^^^^^^^^^^
  File "/home/hk/.local/lib/python3.12/site-packages/sqlalchemy/engine/default.py", line 620, in connect
    return self.loaded_dbapi.connect(*cargs, **cparams)
           ^^^^^^^^^^^^^^^^^^^^^^^^^^^^^^^^^^^^^^^^^^^^
  File "/usr/local/lib/python3.12/dist-packages/MySQLdb/__init__.py", line 121, in Connect
    return Connection(*args, **kwargs)
           ^^^^^^^^^^^^^^^^^^^^^^^^^^^
  File "/usr/local/lib/python3.12/dist-packages/MySQLdb/connections.py", line 195, in __init__
    super().__init__(*args, **kwargs2)
sqlalchemy.exc.OperationalError: (MySQLdb.OperationalError) (2002, "Can't connect to local MySQL server through socket '/var/run/mysqld/mysqld.sock' (2)")
(Background on this error at: https://sqlalche.me/e/20/e3q8)
[2024-06-28 13:19:05 +0300] [2712] [INFO] Worker exiting (pid: 2712)
[2024-06-28 13:19:03 +0300] [2710] [ERROR] Exception in worker process
Traceback (most recent call last):
  File "/home/hk/.local/lib/python3.12/site-packages/sqlalchemy/engine/base.py", line 146, in __init__
    self._dbapi_connection = engine.raw_connection()
                             ^^^^^^^^^^^^^^^^^^^^^^^
  File "/home/hk/.local/lib/python3.12/site-packages/sqlalchemy/engine/base.py", line 3300, in raw_connection
    return self.pool.connect()
           ^^^^^^^^^^^^^^^^^^^
  File "/home/hk/.local/lib/python3.12/site-packages/sqlalchemy/pool/base.py", line 449, in connect
    return _ConnectionFairy._checkout(self)
           ^^^^^^^^^^^^^^^^^^^^^^^^^^^^^^^^
  File "/home/hk/.local/lib/python3.12/site-packages/sqlalchemy/pool/base.py", line 1263, in _checkout
    fairy = _ConnectionRecord.checkout(pool)
            ^^^^^^^^^^^^^^^^^^^^^^^^^^^^^^^^
  File "/home/hk/.local/lib/python3.12/site-packages/sqlalchemy/pool/base.py", line 712, in checkout
    rec = pool._do_get()
          ^^^^^^^^^^^^^^
  File "/home/hk/.local/lib/python3.12/site-packages/sqlalchemy/pool/impl.py", line 179, in _do_get
    with util.safe_reraise():
  File "/home/hk/.local/lib/python3.12/site-packages/sqlalchemy/util/langhelpers.py", line 146, in __exit__
    raise exc_value.with_traceback(exc_tb)
  File "/home/hk/.local/lib/python3.12/site-packages/sqlalchemy/pool/impl.py", line 177, in _do_get
    return self._create_connection()
           ^^^^^^^^^^^^^^^^^^^^^^^^^
  File "/home/hk/.local/lib/python3.12/site-packages/sqlalchemy/pool/base.py", line 390, in _create_connection
    return _ConnectionRecord(self)
           ^^^^^^^^^^^^^^^^^^^^^^^
  File "/home/hk/.local/lib/python3.12/site-packages/sqlalchemy/pool/base.py", line 674, in __init__
    self.__connect()
  File "/home/hk/.local/lib/python3.12/site-packages/sqlalchemy/pool/base.py", line 900, in __connect
    with util.safe_reraise():
  File "/home/hk/.local/lib/python3.12/site-packages/sqlalchemy/util/langhelpers.py", line 146, in __exit__
    raise exc_value.with_traceback(exc_tb)
  File "/home/hk/.local/lib/python3.12/site-packages/sqlalchemy/pool/base.py", line 896, in __connect
    self.dbapi_connection = connection = pool._invoke_creator(self)
                                         ^^^^^^^^^^^^^^^^^^^^^^^^^^
  File "/home/hk/.local/lib/python3.12/site-packages/sqlalchemy/engine/create.py", line 643, in connect
    return dialect.connect(*cargs, **cparams)
           ^^^^^^^^^^^^^^^^^^^^^^^^^^^^^^^^^^
  File "/home/hk/.local/lib/python3.12/site-packages/sqlalchemy/engine/default.py", line 620, in connect
    return self.loaded_dbapi.connect(*cargs, **cparams)
           ^^^^^^^^^^^^^^^^^^^^^^^^^^^^^^^^^^^^^^^^^^^^
  File "/usr/local/lib/python3.12/dist-packages/MySQLdb/__init__.py", line 121, in Connect
    return Connection(*args, **kwargs)
           ^^^^^^^^^^^^^^^^^^^^^^^^^^^
  File "/usr/local/lib/python3.12/dist-packages/MySQLdb/connections.py", line 195, in __init__
    super().__init__(*args, **kwargs2)
MySQLdb.OperationalError: (2002, "Can't connect to local MySQL server through socket '/var/run/mysqld/mysqld.sock' (2)")

The above exception was the direct cause of the following exception:

Traceback (most recent call last):
  File "/usr/lib/python3/dist-packages/gunicorn/arbiter.py", line 589, in spawn_worker
    worker.init_process()
  File "/usr/lib/python3/dist-packages/gunicorn/workers/base.py", line 134, in init_process
    self.load_wsgi()
  File "/usr/lib/python3/dist-packages/gunicorn/workers/base.py", line 146, in load_wsgi
    self.wsgi = self.app.wsgi()
                ^^^^^^^^^^^^^^^
  File "/usr/lib/python3/dist-packages/gunicorn/app/base.py", line 67, in wsgi
    self.callable = self.load()
                    ^^^^^^^^^^^
  File "/usr/lib/python3/dist-packages/gunicorn/app/wsgiapp.py", line 58, in load
    return self.load_wsgiapp()
           ^^^^^^^^^^^^^^^^^^^
  File "/usr/lib/python3/dist-packages/gunicorn/app/wsgiapp.py", line 48, in load_wsgiapp
    return util.import_app(self.app_uri)
           ^^^^^^^^^^^^^^^^^^^^^^^^^^^^^
  File "/usr/lib/python3/dist-packages/gunicorn/util.py", line 384, in import_app
    mod = importlib.import_module(module)
          ^^^^^^^^^^^^^^^^^^^^^^^^^^^^^^^
  File "/usr/lib/python3.12/importlib/__init__.py", line 90, in import_module
    return _bootstrap._gcd_import(name[level:], package, level)
           ^^^^^^^^^^^^^^^^^^^^^^^^^^^^^^^^^^^^^^^^^^^^^^^^^^^^
  File "<frozen importlib._bootstrap>", line 1387, in _gcd_import
  File "<frozen importlib._bootstrap>", line 1360, in _find_and_load
  File "<frozen importlib._bootstrap>", line 1331, in _find_and_load_unlocked
  File "<frozen importlib._bootstrap>", line 935, in _load_unlocked
  File "<frozen importlib._bootstrap_external>", line 995, in exec_module
  File "<frozen importlib._bootstrap>", line 488, in _call_with_frames_removed
  File "/home/hk/grocree/webapp/v1/app.py", line 3, in <module>
    from models import Customer, Order, Orderline, Grocery
  File "/home/hk/grocree/models/__init__.py", line 6, in <module>
    storage.reload()
  File "/home/hk/grocree/models/storage/db_storage.py", line 48, in reload
    base.metadata.create_all(self.__engine)
  File "/home/hk/.local/lib/python3.12/site-packages/sqlalchemy/sql/schema.py", line 5857, in create_all
    bind._run_ddl_visitor(
  File "/home/hk/.local/lib/python3.12/site-packages/sqlalchemy/engine/base.py", line 3250, in _run_ddl_visitor
    with self.begin() as conn:
  File "/usr/lib/python3.12/contextlib.py", line 137, in __enter__
    return next(self.gen)
           ^^^^^^^^^^^^^^
  File "/home/hk/.local/lib/python3.12/site-packages/sqlalchemy/engine/base.py", line 3240, in begin
    with self.connect() as conn:
         ^^^^^^^^^^^^^^
  File "/home/hk/.local/lib/python3.12/site-packages/sqlalchemy/engine/base.py", line 3276, in connect
    return self._connection_cls(self)
           ^^^^^^^^^^^^^^^^^^^^^^^^^^
  File "/home/hk/.local/lib/python3.12/site-packages/sqlalchemy/engine/base.py", line 148, in __init__
    Connection._handle_dbapi_exception_noconnection(
  File "/home/hk/.local/lib/python3.12/site-packages/sqlalchemy/engine/base.py", line 2440, in _handle_dbapi_exception_noconnection
    raise sqlalchemy_exception.with_traceback(exc_info[2]) from e
  File "/home/hk/.local/lib/python3.12/site-packages/sqlalchemy/engine/base.py", line 146, in __init__
    self._dbapi_connection = engine.raw_connection()
                             ^^^^^^^^^^^^^^^^^^^^^^^
  File "/home/hk/.local/lib/python3.12/site-packages/sqlalchemy/engine/base.py", line 3300, in raw_connection
    return self.pool.connect()
           ^^^^^^^^^^^^^^^^^^^
  File "/home/hk/.local/lib/python3.12/site-packages/sqlalchemy/pool/base.py", line 449, in connect
    return _ConnectionFairy._checkout(self)
           ^^^^^^^^^^^^^^^^^^^^^^^^^^^^^^^^
  File "/home/hk/.local/lib/python3.12/site-packages/sqlalchemy/pool/base.py", line 1263, in _checkout
    fairy = _ConnectionRecord.checkout(pool)
            ^^^^^^^^^^^^^^^^^^^^^^^^^^^^^^^^
  File "/home/hk/.local/lib/python3.12/site-packages/sqlalchemy/pool/base.py", line 712, in checkout
    rec = pool._do_get()
          ^^^^^^^^^^^^^^
  File "/home/hk/.local/lib/python3.12/site-packages/sqlalchemy/pool/impl.py", line 179, in _do_get
    with util.safe_reraise():
  File "/home/hk/.local/lib/python3.12/site-packages/sqlalchemy/util/langhelpers.py", line 146, in __exit__
    raise exc_value.with_traceback(exc_tb)
  File "/home/hk/.local/lib/python3.12/site-packages/sqlalchemy/pool/impl.py", line 177, in _do_get
    return self._create_connection()
           ^^^^^^^^^^^^^^^^^^^^^^^^^
  File "/home/hk/.local/lib/python3.12/site-packages/sqlalchemy/pool/base.py", line 390, in _create_connection
    return _ConnectionRecord(self)
           ^^^^^^^^^^^^^^^^^^^^^^^
  File "/home/hk/.local/lib/python3.12/site-packages/sqlalchemy/pool/base.py", line 674, in __init__
    self.__connect()
  File "/home/hk/.local/lib/python3.12/site-packages/sqlalchemy/pool/base.py", line 900, in __connect
    with util.safe_reraise():
  File "/home/hk/.local/lib/python3.12/site-packages/sqlalchemy/util/langhelpers.py", line 146, in __exit__
    raise exc_value.with_traceback(exc_tb)
  File "/home/hk/.local/lib/python3.12/site-packages/sqlalchemy/pool/base.py", line 896, in __connect
    self.dbapi_connection = connection = pool._invoke_creator(self)
                                         ^^^^^^^^^^^^^^^^^^^^^^^^^^
  File "/home/hk/.local/lib/python3.12/site-packages/sqlalchemy/engine/create.py", line 643, in connect
    return dialect.connect(*cargs, **cparams)
           ^^^^^^^^^^^^^^^^^^^^^^^^^^^^^^^^^^
  File "/home/hk/.local/lib/python3.12/site-packages/sqlalchemy/engine/default.py", line 620, in connect
    return self.loaded_dbapi.connect(*cargs, **cparams)
           ^^^^^^^^^^^^^^^^^^^^^^^^^^^^^^^^^^^^^^^^^^^^
  File "/usr/local/lib/python3.12/dist-packages/MySQLdb/__init__.py", line 121, in Connect
    return Connection(*args, **kwargs)
           ^^^^^^^^^^^^^^^^^^^^^^^^^^^
  File "/usr/local/lib/python3.12/dist-packages/MySQLdb/connections.py", line 195, in __init__
    super().__init__(*args, **kwargs2)
sqlalchemy.exc.OperationalError: (MySQLdb.OperationalError) (2002, "Can't connect to local MySQL server through socket '/var/run/mysqld/mysqld.sock' (2)")
(Background on this error at: https://sqlalche.me/e/20/e3q8)
[2024-06-28 13:19:03 +0300] [2711] [ERROR] Exception in worker process
Traceback (most recent call last):
  File "/home/hk/.local/lib/python3.12/site-packages/sqlalchemy/engine/base.py", line 146, in __init__
    self._dbapi_connection = engine.raw_connection()
                             ^^^^^^^^^^^^^^^^^^^^^^^
  File "/home/hk/.local/lib/python3.12/site-packages/sqlalchemy/engine/base.py", line 3300, in raw_connection
    return self.pool.connect()
           ^^^^^^^^^^^^^^^^^^^
  File "/home/hk/.local/lib/python3.12/site-packages/sqlalchemy/pool/base.py", line 449, in connect
    return _ConnectionFairy._checkout(self)
           ^^^^^^^^^^^^^^^^^^^^^^^^^^^^^^^^
  File "/home/hk/.local/lib/python3.12/site-packages/sqlalchemy/pool/base.py", line 1263, in _checkout
    fairy = _ConnectionRecord.checkout(pool)
            ^^^^^^^^^^^^^^^^^^^^^^^^^^^^^^^^
  File "/home/hk/.local/lib/python3.12/site-packages/sqlalchemy/pool/base.py", line 712, in checkout
    rec = pool._do_get()
          ^^^^^^^^^^^^^^
  File "/home/hk/.local/lib/python3.12/site-packages/sqlalchemy/pool/impl.py", line 179, in _do_get
    with util.safe_reraise():
  File "/home/hk/.local/lib/python3.12/site-packages/sqlalchemy/util/langhelpers.py", line 146, in __exit__
    raise exc_value.with_traceback(exc_tb)
  File "/home/hk/.local/lib/python3.12/site-packages/sqlalchemy/pool/impl.py", line 177, in _do_get
    return self._create_connection()
           ^^^^^^^^^^^^^^^^^^^^^^^^^
  File "/home/hk/.local/lib/python3.12/site-packages/sqlalchemy/pool/base.py", line 390, in _create_connection
    return _ConnectionRecord(self)
           ^^^^^^^^^^^^^^^^^^^^^^^
  File "/home/hk/.local/lib/python3.12/site-packages/sqlalchemy/pool/base.py", line 674, in __init__
    self.__connect()
  File "/home/hk/.local/lib/python3.12/site-packages/sqlalchemy/pool/base.py", line 900, in __connect
    with util.safe_reraise():
  File "/home/hk/.local/lib/python3.12/site-packages/sqlalchemy/util/langhelpers.py", line 146, in __exit__
    raise exc_value.with_traceback(exc_tb)
  File "/home/hk/.local/lib/python3.12/site-packages/sqlalchemy/pool/base.py", line 896, in __connect
    self.dbapi_connection = connection = pool._invoke_creator(self)
                                         ^^^^^^^^^^^^^^^^^^^^^^^^^^
  File "/home/hk/.local/lib/python3.12/site-packages/sqlalchemy/engine/create.py", line 643, in connect
    return dialect.connect(*cargs, **cparams)
           ^^^^^^^^^^^^^^^^^^^^^^^^^^^^^^^^^^
  File "/home/hk/.local/lib/python3.12/site-packages/sqlalchemy/engine/default.py", line 620, in connect
    return self.loaded_dbapi.connect(*cargs, **cparams)
           ^^^^^^^^^^^^^^^^^^^^^^^^^^^^^^^^^^^^^^^^^^^^
  File "/usr/local/lib/python3.12/dist-packages/MySQLdb/__init__.py", line 121, in Connect
    return Connection(*args, **kwargs)
           ^^^^^^^^^^^^^^^^^^^^^^^^^^^
  File "/usr/local/lib/python3.12/dist-packages/MySQLdb/connections.py", line 195, in __init__
    super().__init__(*args, **kwargs2)
MySQLdb.OperationalError: (2002, "Can't connect to local MySQL server through socket '/var/run/mysqld/mysqld.sock' (2)")

The above exception was the direct cause of the following exception:

Traceback (most recent call last):
  File "/usr/lib/python3/dist-packages/gunicorn/arbiter.py", line 589, in spawn_worker
    worker.init_process()
  File "/usr/lib/python3/dist-packages/gunicorn/workers/base.py", line 134, in init_process
    self.load_wsgi()
  File "/usr/lib/python3/dist-packages/gunicorn/workers/base.py", line 146, in load_wsgi
    self.wsgi = self.app.wsgi()
                ^^^^^^^^^^^^^^^
  File "/usr/lib/python3/dist-packages/gunicorn/app/base.py", line 67, in wsgi
    self.callable = self.load()
                    ^^^^^^^^^^^
  File "/usr/lib/python3/dist-packages/gunicorn/app/wsgiapp.py", line 58, in load
    return self.load_wsgiapp()
           ^^^^^^^^^^^^^^^^^^^
  File "/usr/lib/python3/dist-packages/gunicorn/app/wsgiapp.py", line 48, in load_wsgiapp
    return util.import_app(self.app_uri)
           ^^^^^^^^^^^^^^^^^^^^^^^^^^^^^
  File "/usr/lib/python3/dist-packages/gunicorn/util.py", line 384, in import_app
    mod = importlib.import_module(module)
          ^^^^^^^^^^^^^^^^^^^^^^^^^^^^^^^
  File "/usr/lib/python3.12/importlib/__init__.py", line 90, in import_module
    return _bootstrap._gcd_import(name[level:], package, level)
           ^^^^^^^^^^^^^^^^^^^^^^^^^^^^^^^^^^^^^^^^^^^^^^^^^^^^
  File "<frozen importlib._bootstrap>", line 1387, in _gcd_import
  File "<frozen importlib._bootstrap>", line 1360, in _find_and_load
  File "<frozen importlib._bootstrap>", line 1331, in _find_and_load_unlocked
  File "<frozen importlib._bootstrap>", line 935, in _load_unlocked
  File "<frozen importlib._bootstrap_external>", line 995, in exec_module
  File "<frozen importlib._bootstrap>", line 488, in _call_with_frames_removed
  File "/home/hk/grocree/webapp/v1/app.py", line 3, in <module>
    from models import Customer, Order, Orderline, Grocery
  File "/home/hk/grocree/models/__init__.py", line 6, in <module>
    storage.reload()
  File "/home/hk/grocree/models/storage/db_storage.py", line 48, in reload
    base.metadata.create_all(self.__engine)
  File "/home/hk/.local/lib/python3.12/site-packages/sqlalchemy/sql/schema.py", line 5857, in create_all
    bind._run_ddl_visitor(
  File "/home/hk/.local/lib/python3.12/site-packages/sqlalchemy/engine/base.py", line 3250, in _run_ddl_visitor
    with self.begin() as conn:
  File "/usr/lib/python3.12/contextlib.py", line 137, in __enter__
    return next(self.gen)
           ^^^^^^^^^^^^^^
  File "/home/hk/.local/lib/python3.12/site-packages/sqlalchemy/engine/base.py", line 3240, in begin
    with self.connect() as conn:
         ^^^^^^^^^^^^^^
  File "/home/hk/.local/lib/python3.12/site-packages/sqlalchemy/engine/base.py", line 3276, in connect
    return self._connection_cls(self)
           ^^^^^^^^^^^^^^^^^^^^^^^^^^
  File "/home/hk/.local/lib/python3.12/site-packages/sqlalchemy/engine/base.py", line 148, in __init__
    Connection._handle_dbapi_exception_noconnection(
  File "/home/hk/.local/lib/python3.12/site-packages/sqlalchemy/engine/base.py", line 2440, in _handle_dbapi_exception_noconnection
    raise sqlalchemy_exception.with_traceback(exc_info[2]) from e
  File "/home/hk/.local/lib/python3.12/site-packages/sqlalchemy/engine/base.py", line 146, in __init__
    self._dbapi_connection = engine.raw_connection()
                             ^^^^^^^^^^^^^^^^^^^^^^^
  File "/home/hk/.local/lib/python3.12/site-packages/sqlalchemy/engine/base.py", line 3300, in raw_connection
    return self.pool.connect()
           ^^^^^^^^^^^^^^^^^^^
  File "/home/hk/.local/lib/python3.12/site-packages/sqlalchemy/pool/base.py", line 449, in connect
    return _ConnectionFairy._checkout(self)
           ^^^^^^^^^^^^^^^^^^^^^^^^^^^^^^^^
  File "/home/hk/.local/lib/python3.12/site-packages/sqlalchemy/pool/base.py", line 1263, in _checkout
    fairy = _ConnectionRecord.checkout(pool)
            ^^^^^^^^^^^^^^^^^^^^^^^^^^^^^^^^
  File "/home/hk/.local/lib/python3.12/site-packages/sqlalchemy/pool/base.py", line 712, in checkout
    rec = pool._do_get()
          ^^^^^^^^^^^^^^
  File "/home/hk/.local/lib/python3.12/site-packages/sqlalchemy/pool/impl.py", line 179, in _do_get
    with util.safe_reraise():
  File "/home/hk/.local/lib/python3.12/site-packages/sqlalchemy/util/langhelpers.py", line 146, in __exit__
    raise exc_value.with_traceback(exc_tb)
  File "/home/hk/.local/lib/python3.12/site-packages/sqlalchemy/pool/impl.py", line 177, in _do_get
    return self._create_connection()
           ^^^^^^^^^^^^^^^^^^^^^^^^^
  File "/home/hk/.local/lib/python3.12/site-packages/sqlalchemy/pool/base.py", line 390, in _create_connection
    return _ConnectionRecord(self)
           ^^^^^^^^^^^^^^^^^^^^^^^
  File "/home/hk/.local/lib/python3.12/site-packages/sqlalchemy/pool/base.py", line 674, in __init__
    self.__connect()
  File "/home/hk/.local/lib/python3.12/site-packages/sqlalchemy/pool/base.py", line 900, in __connect
    with util.safe_reraise():
  File "/home/hk/.local/lib/python3.12/site-packages/sqlalchemy/util/langhelpers.py", line 146, in __exit__
    raise exc_value.with_traceback(exc_tb)
  File "/home/hk/.local/lib/python3.12/site-packages/sqlalchemy/pool/base.py", line 896, in __connect
    self.dbapi_connection = connection = pool._invoke_creator(self)
                                         ^^^^^^^^^^^^^^^^^^^^^^^^^^
  File "/home/hk/.local/lib/python3.12/site-packages/sqlalchemy/engine/create.py", line 643, in connect
    return dialect.connect(*cargs, **cparams)
           ^^^^^^^^^^^^^^^^^^^^^^^^^^^^^^^^^^
  File "/home/hk/.local/lib/python3.12/site-packages/sqlalchemy/engine/default.py", line 620, in connect
    return self.loaded_dbapi.connect(*cargs, **cparams)
           ^^^^^^^^^^^^^^^^^^^^^^^^^^^^^^^^^^^^^^^^^^^^
  File "/usr/local/lib/python3.12/dist-packages/MySQLdb/__init__.py", line 121, in Connect
    return Connection(*args, **kwargs)
           ^^^^^^^^^^^^^^^^^^^^^^^^^^^
  File "/usr/local/lib/python3.12/dist-packages/MySQLdb/connections.py", line 195, in __init__
    super().__init__(*args, **kwargs2)
sqlalchemy.exc.OperationalError: (MySQLdb.OperationalError) (2002, "Can't connect to local MySQL server through socket '/var/run/mysqld/mysqld.sock' (2)")
(Background on this error at: https://sqlalche.me/e/20/e3q8)
[2024-06-28 13:19:05 +0300] [2710] [INFO] Worker exiting (pid: 2710)
[2024-06-28 13:19:05 +0300] [2711] [INFO] Worker exiting (pid: 2711)
[2024-06-28 13:22:55 +0300] [6002] [INFO] Starting gunicorn 20.1.0
[2024-06-28 13:22:55 +0300] [6002] [INFO] Listening at: http://127.0.0.1:8000 (6002)
[2024-06-28 13:22:55 +0300] [6002] [INFO] Using worker: sync
[2024-06-28 13:22:55 +0300] [6007] [INFO] Booting worker with pid: 6007
[2024-06-28 13:22:55 +0300] [6008] [INFO] Booting worker with pid: 6008
[2024-06-28 13:22:55 +0300] [6010] [INFO] Booting worker with pid: 6010
[2024-06-28 13:25:11 +0300] [6007] [INFO] Worker exiting (pid: 6007)
[2024-06-28 13:25:11 +0300] [6008] [INFO] Worker exiting (pid: 6008)
[2024-06-28 13:25:11 +0300] [6002] [INFO] Handling signal: term
[2024-06-28 13:25:11 +0300] [6010] [INFO] Worker exiting (pid: 6010)
[2024-06-28 13:25:11 +0300] [6002] [WARNING] Worker with pid 6010 was terminated due to signal 15
[2024-06-28 13:25:11 +0300] [6002] [INFO] Shutting down: Master
[2024-06-28 13:25:11 +0300] [6838] [INFO] Starting gunicorn 20.1.0
[2024-06-28 13:25:11 +0300] [6838] [INFO] Listening at: http://127.0.0.1:8000 (6838)
[2024-06-28 13:25:11 +0300] [6838] [INFO] Using worker: sync
[2024-06-28 13:25:11 +0300] [6841] [INFO] Booting worker with pid: 6841
[2024-06-28 13:25:11 +0300] [6842] [INFO] Booting worker with pid: 6842
[2024-06-28 13:25:11 +0300] [6843] [INFO] Booting worker with pid: 6843
[2024-06-28 13:28:18 +0300] [6992] [INFO] Starting gunicorn 20.1.0
[2024-06-28 13:28:18 +0300] [6992] [ERROR] Connection in use: ('localhost', 8000)
[2024-06-28 13:28:18 +0300] [6992] [ERROR] Retrying in 1 second.
[2024-06-28 13:28:19 +0300] [6992] [ERROR] Connection in use: ('localhost', 8000)
[2024-06-28 13:28:19 +0300] [6992] [ERROR] Retrying in 1 second.
[2024-06-28 13:28:20 +0300] [6992] [ERROR] Connection in use: ('localhost', 8000)
[2024-06-28 13:28:20 +0300] [6992] [ERROR] Retrying in 1 second.
[2024-06-28 13:28:21 +0300] [6992] [ERROR] Connection in use: ('localhost', 8000)
[2024-06-28 13:28:21 +0300] [6992] [ERROR] Retrying in 1 second.
[2024-06-28 13:28:22 +0300] [6992] [ERROR] Connection in use: ('localhost', 8000)
[2024-06-28 13:28:22 +0300] [6992] [ERROR] Retrying in 1 second.
[2024-06-28 13:28:23 +0300] [6992] [ERROR] Can't connect to ('localhost', 8000)
[2024-06-28 13:29:16 +0300] [7057] [INFO] Starting gunicorn 20.1.0
[2024-06-28 13:29:16 +0300] [7057] [INFO] Listening at: http://127.0.0.1:8080 (7057)
[2024-06-28 13:29:16 +0300] [7057] [INFO] Using worker: sync
[2024-06-28 13:29:16 +0300] [7058] [INFO] Booting worker with pid: 7058
[2024-06-28 13:29:16 +0300] [7059] [INFO] Booting worker with pid: 7059
[2024-06-28 13:29:16 +0300] [7060] [INFO] Booting worker with pid: 7060
[2024-06-28 13:29:40 +0300] [7057] [INFO] Handling signal: winch
[2024-06-28 13:29:41 +0300] [7057] [INFO] Handling signal: int
[2024-06-28 13:29:41 +0300] [7059] [INFO] Worker exiting (pid: 7059)
[2024-06-28 13:29:41 +0300] [7060] [INFO] Worker exiting (pid: 7060)
[2024-06-28 13:29:41 +0300] [7058] [INFO] Worker exiting (pid: 7058)
[2024-06-28 13:29:42 +0300] [7057] [INFO] Shutting down: Master
[2024-06-28 13:32:20 +0300] [6842] [INFO] Worker exiting (pid: 6842)
[2024-06-28 13:32:20 +0300] [6841] [INFO] Worker exiting (pid: 6841)
[2024-06-28 13:32:20 +0300] [6838] [INFO] Handling signal: term
[2024-06-28 13:32:20 +0300] [6843] [INFO] Worker exiting (pid: 6843)
[2024-06-28 13:32:20 +0300] [6838] [WARNING] Worker with pid 6843 was terminated due to signal 15
[2024-06-28 13:32:20 +0300] [6838] [INFO] Shutting down: Master
[2024-06-28 13:32:20 +0300] [7485] [INFO] Starting gunicorn 20.1.0
[2024-06-28 13:32:20 +0300] [7485] [INFO] Listening at: http://127.0.0.1:8080 (7485)
[2024-06-28 13:32:20 +0300] [7485] [INFO] Using worker: sync
[2024-06-28 13:32:20 +0300] [7487] [INFO] Booting worker with pid: 7487
[2024-06-28 13:32:21 +0300] [7488] [INFO] Booting worker with pid: 7488
[2024-06-28 13:32:21 +0300] [7489] [INFO] Booting worker with pid: 7489
[2024-06-28 13:33:11 +0300] [7485] [INFO] Handling signal: term
[2024-06-28 13:33:11 +0300] [7488] [INFO] Worker exiting (pid: 7488)
[2024-06-28 13:33:11 +0300] [7487] [INFO] Worker exiting (pid: 7487)
[2024-06-28 13:33:11 +0300] [7489] [INFO] Worker exiting (pid: 7489)
[2024-06-28 13:33:11 +0300] [7485] [INFO] Shutting down: Master
[2024-06-28 13:40:56 +0300] [7266] [INFO] Starting gunicorn 20.1.0
[2024-06-28 13:40:56 +0300] [7266] [INFO] Listening at: http://127.0.0.1:8080 (7266)
[2024-06-28 13:40:56 +0300] [7266] [INFO] Using worker: sync
[2024-06-28 13:40:56 +0300] [7273] [INFO] Booting worker with pid: 7273
[2024-06-28 13:40:56 +0300] [7274] [INFO] Booting worker with pid: 7274
[2024-06-28 13:40:56 +0300] [7275] [INFO] Booting worker with pid: 7275
[2024-06-28 13:49:50 +0300] [7275] [INFO] Worker exiting (pid: 7275)
[2024-06-28 13:49:50 +0300] [7274] [INFO] Worker exiting (pid: 7274)
[2024-06-28 13:49:50 +0300] [7273] [INFO] Worker exiting (pid: 7273)
[2024-06-28 13:49:50 +0300] [7266] [INFO] Handling signal: term
[2024-06-28 13:49:58 +0300] [7266] [WARNING] Worker with pid 7273 was terminated due to signal 15
[2024-06-28 13:49:59 +0300] [7266] [WARNING] Worker with pid 7274 was terminated due to signal 15
[2024-06-28 13:49:59 +0300] [7266] [WARNING] Worker with pid 7275 was terminated due to signal 15
[2024-06-28 13:50:00 +0300] [7266] [INFO] Shutting down: Master
[2024-06-28 13:50:10 +0300] [8681] [INFO] Starting gunicorn 20.1.0
[2024-06-28 13:50:10 +0300] [8681] [INFO] Listening at: http://127.0.0.1:8080 (8681)
[2024-06-28 13:50:10 +0300] [8681] [INFO] Using worker: sync
[2024-06-28 13:50:10 +0300] [8682] [INFO] Booting worker with pid: 8682
[2024-06-28 13:50:10 +0300] [8683] [INFO] Booting worker with pid: 8683
[2024-06-28 13:50:10 +0300] [8684] [INFO] Booting worker with pid: 8684
[2024-06-28 13:50:16 +0300] [8682] [INFO] Worker exiting (pid: 8682)
[2024-06-28 13:50:16 +0300] [8681] [INFO] Handling signal: term
[2024-06-28 13:50:16 +0300] [8683] [INFO] Worker exiting (pid: 8683)
[2024-06-28 13:50:16 +0300] [8684] [INFO] Worker exiting (pid: 8684)
[2024-06-28 13:50:17 +0300] [8681] [INFO] Shutting down: Master
[2024-06-28 13:52:12 +0300] [2568] [INFO] Starting gunicorn 20.1.0
[2024-06-28 13:52:12 +0300] [2568] [INFO] Listening at: http://127.0.0.1:8080 (2568)
[2024-06-28 13:52:12 +0300] [2568] [INFO] Using worker: sync
[2024-06-28 13:52:12 +0300] [2716] [INFO] Booting worker with pid: 2716
[2024-06-28 13:52:12 +0300] [2717] [INFO] Booting worker with pid: 2717
[2024-06-28 13:52:13 +0300] [2718] [INFO] Booting worker with pid: 2718
[2024-06-28 13:52:34 +0300] [2718] [ERROR] Exception in worker process
Traceback (most recent call last):
  File "/home/hk/.local/lib/python3.12/site-packages/sqlalchemy/engine/base.py", line 146, in __init__
    self._dbapi_connection = engine.raw_connection()
                             ^^^^^^^^^^^^^^^^^^^^^^^
  File "/home/hk/.local/lib/python3.12/site-packages/sqlalchemy/engine/base.py", line 3300, in raw_connection
    return self.pool.connect()
           ^^^^^^^^^^^^^^^^^^^
  File "/home/hk/.local/lib/python3.12/site-packages/sqlalchemy/pool/base.py", line 449, in connect
    return _ConnectionFairy._checkout(self)
           ^^^^^^^^^^^^^^^^^^^^^^^^^^^^^^^^
  File "/home/hk/.local/lib/python3.12/site-packages/sqlalchemy/pool/base.py", line 1263, in _checkout
    fairy = _ConnectionRecord.checkout(pool)
            ^^^^^^^^^^^^^^^^^^^^^^^^^^^^^^^^
  File "/home/hk/.local/lib/python3.12/site-packages/sqlalchemy/pool/base.py", line 712, in checkout
    rec = pool._do_get()
          ^^^^^^^^^^^^^^
  File "/home/hk/.local/lib/python3.12/site-packages/sqlalchemy/pool/impl.py", line 179, in _do_get
    with util.safe_reraise():
  File "/home/hk/.local/lib/python3.12/site-packages/sqlalchemy/util/langhelpers.py", line 146, in __exit__
    raise exc_value.with_traceback(exc_tb)
  File "/home/hk/.local/lib/python3.12/site-packages/sqlalchemy/pool/impl.py", line 177, in _do_get
    return self._create_connection()
           ^^^^^^^^^^^^^^^^^^^^^^^^^
  File "/home/hk/.local/lib/python3.12/site-packages/sqlalchemy/pool/base.py", line 390, in _create_connection
    return _ConnectionRecord(self)
           ^^^^^^^^^^^^^^^^^^^^^^^
  File "/home/hk/.local/lib/python3.12/site-packages/sqlalchemy/pool/base.py", line 674, in __init__
    self.__connect()
  File "/home/hk/.local/lib/python3.12/site-packages/sqlalchemy/pool/base.py", line 900, in __connect
    with util.safe_reraise():
  File "/home/hk/.local/lib/python3.12/site-packages/sqlalchemy/util/langhelpers.py", line 146, in __exit__
    raise exc_value.with_traceback(exc_tb)
  File "/home/hk/.local/lib/python3.12/site-packages/sqlalchemy/pool/base.py", line 896, in __connect
    self.dbapi_connection = connection = pool._invoke_creator(self)
                                         ^^^^^^^^^^^^^^^^^^^^^^^^^^
  File "/home/hk/.local/lib/python3.12/site-packages/sqlalchemy/engine/create.py", line 643, in connect
    return dialect.connect(*cargs, **cparams)
           ^^^^^^^^^^^^^^^^^^^^^^^^^^^^^^^^^^
  File "/home/hk/.local/lib/python3.12/site-packages/sqlalchemy/engine/default.py", line 620, in connect
    return self.loaded_dbapi.connect(*cargs, **cparams)
           ^^^^^^^^^^^^^^^^^^^^^^^^^^^^^^^^^^^^^^^^^^^^
  File "/usr/local/lib/python3.12/dist-packages/MySQLdb/__init__.py", line 121, in Connect
    return Connection(*args, **kwargs)
           ^^^^^^^^^^^^^^^^^^^^^^^^^^^
  File "/usr/local/lib/python3.12/dist-packages/MySQLdb/connections.py", line 195, in __init__
    super().__init__(*args, **kwargs2)
MySQLdb.OperationalError: (2002, "Can't connect to local MySQL server through socket '/var/run/mysqld/mysqld.sock' (2)")

The above exception was the direct cause of the following exception:

Traceback (most recent call last):
  File "/usr/lib/python3/dist-packages/gunicorn/arbiter.py", line 589, in spawn_worker
    worker.init_process()
  File "/usr/lib/python3/dist-packages/gunicorn/workers/base.py", line 134, in init_process
    self.load_wsgi()
  File "/usr/lib/python3/dist-packages/gunicorn/workers/base.py", line 146, in load_wsgi
    self.wsgi = self.app.wsgi()
                ^^^^^^^^^^^^^^^
  File "/usr/lib/python3/dist-packages/gunicorn/app/base.py", line 67, in wsgi
    self.callable = self.load()
                    ^^^^^^^^^^^
  File "/usr/lib/python3/dist-packages/gunicorn/app/wsgiapp.py", line 58, in load
    return self.load_wsgiapp()
           ^^^^^^^^^^^^^^^^^^^
  File "/usr/lib/python3/dist-packages/gunicorn/app/wsgiapp.py", line 48, in load_wsgiapp
    return util.import_app(self.app_uri)
           ^^^^^^^^^^^^^^^^^^^^^^^^^^^^^
  File "/usr/lib/python3/dist-packages/gunicorn/util.py", line 384, in import_app
    mod = importlib.import_module(module)
          ^^^^^^^^^^^^^^^^^^^^^^^^^^^^^^^
  File "/usr/lib/python3.12/importlib/__init__.py", line 90, in import_module
    return _bootstrap._gcd_import(name[level:], package, level)
           ^^^^^^^^^^^^^^^^^^^^^^^^^^^^^^^^^^^^^^^^^^^^^^^^^^^^
  File "<frozen importlib._bootstrap>", line 1387, in _gcd_import
  File "<frozen importlib._bootstrap>", line 1360, in _find_and_load
  File "<frozen importlib._bootstrap>", line 1331, in _find_and_load_unlocked
  File "<frozen importlib._bootstrap>", line 935, in _load_unlocked
  File "<frozen importlib._bootstrap_external>", line 995, in exec_module
  File "<frozen importlib._bootstrap>", line 488, in _call_with_frames_removed
  File "/home/hk/grocree/webapp/v1/app.py", line 3, in <module>
    from models import Customer, Order, Orderline, Grocery
  File "/home/hk/grocree/models/__init__.py", line 6, in <module>
    storage.reload()
  File "/home/hk/grocree/models/storage/db_storage.py", line 48, in reload
    base.metadata.create_all(self.__engine)
  File "/home/hk/.local/lib/python3.12/site-packages/sqlalchemy/sql/schema.py", line 5857, in create_all
    bind._run_ddl_visitor(
  File "/home/hk/.local/lib/python3.12/site-packages/sqlalchemy/engine/base.py", line 3250, in _run_ddl_visitor
    with self.begin() as conn:
  File "/usr/lib/python3.12/contextlib.py", line 137, in __enter__
    return next(self.gen)
           ^^^^^^^^^^^^^^
  File "/home/hk/.local/lib/python3.12/site-packages/sqlalchemy/engine/base.py", line 3240, in begin
    with self.connect() as conn:
         ^^^^^^^^^^^^^^
  File "/home/hk/.local/lib/python3.12/site-packages/sqlalchemy/engine/base.py", line 3276, in connect
    return self._connection_cls(self)
           ^^^^^^^^^^^^^^^^^^^^^^^^^^
  File "/home/hk/.local/lib/python3.12/site-packages/sqlalchemy/engine/base.py", line 148, in __init__
    Connection._handle_dbapi_exception_noconnection(
  File "/home/hk/.local/lib/python3.12/site-packages/sqlalchemy/engine/base.py", line 2440, in _handle_dbapi_exception_noconnection
    raise sqlalchemy_exception.with_traceback(exc_info[2]) from e
  File "/home/hk/.local/lib/python3.12/site-packages/sqlalchemy/engine/base.py", line 146, in __init__
    self._dbapi_connection = engine.raw_connection()
                             ^^^^^^^^^^^^^^^^^^^^^^^
  File "/home/hk/.local/lib/python3.12/site-packages/sqlalchemy/engine/base.py", line 3300, in raw_connection
    return self.pool.connect()
           ^^^^^^^^^^^^^^^^^^^
  File "/home/hk/.local/lib/python3.12/site-packages/sqlalchemy/pool/base.py", line 449, in connect
    return _ConnectionFairy._checkout(self)
           ^^^^^^^^^^^^^^^^^^^^^^^^^^^^^^^^
  File "/home/hk/.local/lib/python3.12/site-packages/sqlalchemy/pool/base.py", line 1263, in _checkout
    fairy = _ConnectionRecord.checkout(pool)
            ^^^^^^^^^^^^^^^^^^^^^^^^^^^^^^^^
  File "/home/hk/.local/lib/python3.12/site-packages/sqlalchemy/pool/base.py", line 712, in checkout
    rec = pool._do_get()
          ^^^^^^^^^^^^^^
  File "/home/hk/.local/lib/python3.12/site-packages/sqlalchemy/pool/impl.py", line 179, in _do_get
    with util.safe_reraise():
  File "/home/hk/.local/lib/python3.12/site-packages/sqlalchemy/util/langhelpers.py", line 146, in __exit__
    raise exc_value.with_traceback(exc_tb)
  File "/home/hk/.local/lib/python3.12/site-packages/sqlalchemy/pool/impl.py", line 177, in _do_get
    return self._create_connection()
           ^^^^^^^^^^^^^^^^^^^^^^^^^
  File "/home/hk/.local/lib/python3.12/site-packages/sqlalchemy/pool/base.py", line 390, in _create_connection
    return _ConnectionRecord(self)
           ^^^^^^^^^^^^^^^^^^^^^^^
  File "/home/hk/.local/lib/python3.12/site-packages/sqlalchemy/pool/base.py", line 674, in __init__
    self.__connect()
  File "/home/hk/.local/lib/python3.12/site-packages/sqlalchemy/pool/base.py", line 900, in __connect
    with util.safe_reraise():
  File "/home/hk/.local/lib/python3.12/site-packages/sqlalchemy/util/langhelpers.py", line 146, in __exit__
    raise exc_value.with_traceback(exc_tb)
  File "/home/hk/.local/lib/python3.12/site-packages/sqlalchemy/pool/base.py", line 896, in __connect
    self.dbapi_connection = connection = pool._invoke_creator(self)
                                         ^^^^^^^^^^^^^^^^^^^^^^^^^^
  File "/home/hk/.local/lib/python3.12/site-packages/sqlalchemy/engine/create.py", line 643, in connect
    return dialect.connect(*cargs, **cparams)
           ^^^^^^^^^^^^^^^^^^^^^^^^^^^^^^^^^^
  File "/home/hk/.local/lib/python3.12/site-packages/sqlalchemy/engine/default.py", line 620, in connect
    return self.loaded_dbapi.connect(*cargs, **cparams)
           ^^^^^^^^^^^^^^^^^^^^^^^^^^^^^^^^^^^^^^^^^^^^
  File "/usr/local/lib/python3.12/dist-packages/MySQLdb/__init__.py", line 121, in Connect
    return Connection(*args, **kwargs)
           ^^^^^^^^^^^^^^^^^^^^^^^^^^^
  File "/usr/local/lib/python3.12/dist-packages/MySQLdb/connections.py", line 195, in __init__
    super().__init__(*args, **kwargs2)
sqlalchemy.exc.OperationalError: (MySQLdb.OperationalError) (2002, "Can't connect to local MySQL server through socket '/var/run/mysqld/mysqld.sock' (2)")
(Background on this error at: https://sqlalche.me/e/20/e3q8)
[2024-06-28 13:52:35 +0300] [2718] [INFO] Worker exiting (pid: 2718)
[2024-06-28 13:52:34 +0300] [2716] [ERROR] Exception in worker process
Traceback (most recent call last):
  File "/home/hk/.local/lib/python3.12/site-packages/sqlalchemy/engine/base.py", line 146, in __init__
    self._dbapi_connection = engine.raw_connection()
                             ^^^^^^^^^^^^^^^^^^^^^^^
  File "/home/hk/.local/lib/python3.12/site-packages/sqlalchemy/engine/base.py", line 3300, in raw_connection
    return self.pool.connect()
           ^^^^^^^^^^^^^^^^^^^
  File "/home/hk/.local/lib/python3.12/site-packages/sqlalchemy/pool/base.py", line 449, in connect
    return _ConnectionFairy._checkout(self)
           ^^^^^^^^^^^^^^^^^^^^^^^^^^^^^^^^
  File "/home/hk/.local/lib/python3.12/site-packages/sqlalchemy/pool/base.py", line 1263, in _checkout
    fairy = _ConnectionRecord.checkout(pool)
            ^^^^^^^^^^^^^^^^^^^^^^^^^^^^^^^^
  File "/home/hk/.local/lib/python3.12/site-packages/sqlalchemy/pool/base.py", line 712, in checkout
    rec = pool._do_get()
          ^^^^^^^^^^^^^^
  File "/home/hk/.local/lib/python3.12/site-packages/sqlalchemy/pool/impl.py", line 179, in _do_get
    with util.safe_reraise():
  File "/home/hk/.local/lib/python3.12/site-packages/sqlalchemy/util/langhelpers.py", line 146, in __exit__
    raise exc_value.with_traceback(exc_tb)
  File "/home/hk/.local/lib/python3.12/site-packages/sqlalchemy/pool/impl.py", line 177, in _do_get
    return self._create_connection()
           ^^^^^^^^^^^^^^^^^^^^^^^^^
  File "/home/hk/.local/lib/python3.12/site-packages/sqlalchemy/pool/base.py", line 390, in _create_connection
    return _ConnectionRecord(self)
           ^^^^^^^^^^^^^^^^^^^^^^^
  File "/home/hk/.local/lib/python3.12/site-packages/sqlalchemy/pool/base.py", line 674, in __init__
    self.__connect()
  File "/home/hk/.local/lib/python3.12/site-packages/sqlalchemy/pool/base.py", line 900, in __connect
    with util.safe_reraise():
  File "/home/hk/.local/lib/python3.12/site-packages/sqlalchemy/util/langhelpers.py", line 146, in __exit__
    raise exc_value.with_traceback(exc_tb)
  File "/home/hk/.local/lib/python3.12/site-packages/sqlalchemy/pool/base.py", line 896, in __connect
    self.dbapi_connection = connection = pool._invoke_creator(self)
                                         ^^^^^^^^^^^^^^^^^^^^^^^^^^
  File "/home/hk/.local/lib/python3.12/site-packages/sqlalchemy/engine/create.py", line 643, in connect
    return dialect.connect(*cargs, **cparams)
           ^^^^^^^^^^^^^^^^^^^^^^^^^^^^^^^^^^
  File "/home/hk/.local/lib/python3.12/site-packages/sqlalchemy/engine/default.py", line 620, in connect
    return self.loaded_dbapi.connect(*cargs, **cparams)
           ^^^^^^^^^^^^^^^^^^^^^^^^^^^^^^^^^^^^^^^^^^^^
  File "/usr/local/lib/python3.12/dist-packages/MySQLdb/__init__.py", line 121, in Connect
    return Connection(*args, **kwargs)
           ^^^^^^^^^^^^^^^^^^^^^^^^^^^
  File "/usr/local/lib/python3.12/dist-packages/MySQLdb/connections.py", line 195, in __init__
    super().__init__(*args, **kwargs2)
MySQLdb.OperationalError: (2002, "Can't connect to local MySQL server through socket '/var/run/mysqld/mysqld.sock' (2)")

The above exception was the direct cause of the following exception:

Traceback (most recent call last):
  File "/usr/lib/python3/dist-packages/gunicorn/arbiter.py", line 589, in spawn_worker
    worker.init_process()
  File "/usr/lib/python3/dist-packages/gunicorn/workers/base.py", line 134, in init_process
    self.load_wsgi()
  File "/usr/lib/python3/dist-packages/gunicorn/workers/base.py", line 146, in load_wsgi
    self.wsgi = self.app.wsgi()
                ^^^^^^^^^^^^^^^
  File "/usr/lib/python3/dist-packages/gunicorn/app/base.py", line 67, in wsgi
    self.callable = self.load()
                    ^^^^^^^^^^^
  File "/usr/lib/python3/dist-packages/gunicorn/app/wsgiapp.py", line 58, in load
    return self.load_wsgiapp()
           ^^^^^^^^^^^^^^^^^^^
  File "/usr/lib/python3/dist-packages/gunicorn/app/wsgiapp.py", line 48, in load_wsgiapp
    return util.import_app(self.app_uri)
           ^^^^^^^^^^^^^^^^^^^^^^^^^^^^^
  File "/usr/lib/python3/dist-packages/gunicorn/util.py", line 384, in import_app
    mod = importlib.import_module(module)
          ^^^^^^^^^^^^^^^^^^^^^^^^^^^^^^^
  File "/usr/lib/python3.12/importlib/__init__.py", line 90, in import_module
    return _bootstrap._gcd_import(name[level:], package, level)
           ^^^^^^^^^^^^^^^^^^^^^^^^^^^^^^^^^^^^^^^^^^^^^^^^^^^^
  File "<frozen importlib._bootstrap>", line 1387, in _gcd_import
  File "<frozen importlib._bootstrap>", line 1360, in _find_and_load
  File "<frozen importlib._bootstrap>", line 1331, in _find_and_load_unlocked
  File "<frozen importlib._bootstrap>", line 935, in _load_unlocked
  File "<frozen importlib._bootstrap_external>", line 995, in exec_module
  File "<frozen importlib._bootstrap>", line 488, in _call_with_frames_removed
  File "/home/hk/grocree/webapp/v1/app.py", line 3, in <module>
    from models import Customer, Order, Orderline, Grocery
  File "/home/hk/grocree/models/__init__.py", line 6, in <module>
    storage.reload()
  File "/home/hk/grocree/models/storage/db_storage.py", line 48, in reload
    base.metadata.create_all(self.__engine)
  File "/home/hk/.local/lib/python3.12/site-packages/sqlalchemy/sql/schema.py", line 5857, in create_all
    bind._run_ddl_visitor(
  File "/home/hk/.local/lib/python3.12/site-packages/sqlalchemy/engine/base.py", line 3250, in _run_ddl_visitor
    with self.begin() as conn:
  File "/usr/lib/python3.12/contextlib.py", line 137, in __enter__
    return next(self.gen)
           ^^^^^^^^^^^^^^
  File "/home/hk/.local/lib/python3.12/site-packages/sqlalchemy/engine/base.py", line 3240, in begin
    with self.connect() as conn:
         ^^^^^^^^^^^^^^
  File "/home/hk/.local/lib/python3.12/site-packages/sqlalchemy/engine/base.py", line 3276, in connect
    return self._connection_cls(self)
           ^^^^^^^^^^^^^^^^^^^^^^^^^^
  File "/home/hk/.local/lib/python3.12/site-packages/sqlalchemy/engine/base.py", line 148, in __init__
    Connection._handle_dbapi_exception_noconnection(
  File "/home/hk/.local/lib/python3.12/site-packages/sqlalchemy/engine/base.py", line 2440, in _handle_dbapi_exception_noconnection
    raise sqlalchemy_exception.with_traceback(exc_info[2]) from e
  File "/home/hk/.local/lib/python3.12/site-packages/sqlalchemy/engine/base.py", line 146, in __init__
    self._dbapi_connection = engine.raw_connection()
                             ^^^^^^^^^^^^^^^^^^^^^^^
  File "/home/hk/.local/lib/python3.12/site-packages/sqlalchemy/engine/base.py", line 3300, in raw_connection
    return self.pool.connect()
           ^^^^^^^^^^^^^^^^^^^
  File "/home/hk/.local/lib/python3.12/site-packages/sqlalchemy/pool/base.py", line 449, in connect
    return _ConnectionFairy._checkout(self)
           ^^^^^^^^^^^^^^^^^^^^^^^^^^^^^^^^
  File "/home/hk/.local/lib/python3.12/site-packages/sqlalchemy/pool/base.py", line 1263, in _checkout
    fairy = _ConnectionRecord.checkout(pool)
            ^^^^^^^^^^^^^^^^^^^^^^^^^^^^^^^^
  File "/home/hk/.local/lib/python3.12/site-packages/sqlalchemy/pool/base.py", line 712, in checkout
    rec = pool._do_get()
          ^^^^^^^^^^^^^^
  File "/home/hk/.local/lib/python3.12/site-packages/sqlalchemy/pool/impl.py", line 179, in _do_get
    with util.safe_reraise():
  File "/home/hk/.local/lib/python3.12/site-packages/sqlalchemy/util/langhelpers.py", line 146, in __exit__
    raise exc_value.with_traceback(exc_tb)
  File "/home/hk/.local/lib/python3.12/site-packages/sqlalchemy/pool/impl.py", line 177, in _do_get
    return self._create_connection()
           ^^^^^^^^^^^^^^^^^^^^^^^^^
  File "/home/hk/.local/lib/python3.12/site-packages/sqlalchemy/pool/base.py", line 390, in _create_connection
    return _ConnectionRecord(self)
           ^^^^^^^^^^^^^^^^^^^^^^^
  File "/home/hk/.local/lib/python3.12/site-packages/sqlalchemy/pool/base.py", line 674, in __init__
    self.__connect()
  File "/home/hk/.local/lib/python3.12/site-packages/sqlalchemy/pool/base.py", line 900, in __connect
    with util.safe_reraise():
  File "/home/hk/.local/lib/python3.12/site-packages/sqlalchemy/util/langhelpers.py", line 146, in __exit__
    raise exc_value.with_traceback(exc_tb)
  File "/home/hk/.local/lib/python3.12/site-packages/sqlalchemy/pool/base.py", line 896, in __connect
    self.dbapi_connection = connection = pool._invoke_creator(self)
                                         ^^^^^^^^^^^^^^^^^^^^^^^^^^
  File "/home/hk/.local/lib/python3.12/site-packages/sqlalchemy/engine/create.py", line 643, in connect
    return dialect.connect(*cargs, **cparams)
           ^^^^^^^^^^^^^^^^^^^^^^^^^^^^^^^^^^
  File "/home/hk/.local/lib/python3.12/site-packages/sqlalchemy/engine/default.py", line 620, in connect
    return self.loaded_dbapi.connect(*cargs, **cparams)
           ^^^^^^^^^^^^^^^^^^^^^^^^^^^^^^^^^^^^^^^^^^^^
  File "/usr/local/lib/python3.12/dist-packages/MySQLdb/__init__.py", line 121, in Connect
    return Connection(*args, **kwargs)
           ^^^^^^^^^^^^^^^^^^^^^^^^^^^
  File "/usr/local/lib/python3.12/dist-packages/MySQLdb/connections.py", line 195, in __init__
    super().__init__(*args, **kwargs2)
sqlalchemy.exc.OperationalError: (MySQLdb.OperationalError) (2002, "Can't connect to local MySQL server through socket '/var/run/mysqld/mysqld.sock' (2)")
(Background on this error at: https://sqlalche.me/e/20/e3q8)
[2024-06-28 13:52:34 +0300] [2717] [ERROR] Exception in worker process
Traceback (most recent call last):
  File "/home/hk/.local/lib/python3.12/site-packages/sqlalchemy/engine/base.py", line 146, in __init__
    self._dbapi_connection = engine.raw_connection()
                             ^^^^^^^^^^^^^^^^^^^^^^^
  File "/home/hk/.local/lib/python3.12/site-packages/sqlalchemy/engine/base.py", line 3300, in raw_connection
    return self.pool.connect()
           ^^^^^^^^^^^^^^^^^^^
  File "/home/hk/.local/lib/python3.12/site-packages/sqlalchemy/pool/base.py", line 449, in connect
    return _ConnectionFairy._checkout(self)
           ^^^^^^^^^^^^^^^^^^^^^^^^^^^^^^^^
  File "/home/hk/.local/lib/python3.12/site-packages/sqlalchemy/pool/base.py", line 1263, in _checkout
    fairy = _ConnectionRecord.checkout(pool)
            ^^^^^^^^^^^^^^^^^^^^^^^^^^^^^^^^
  File "/home/hk/.local/lib/python3.12/site-packages/sqlalchemy/pool/base.py", line 712, in checkout
    rec = pool._do_get()
          ^^^^^^^^^^^^^^
  File "/home/hk/.local/lib/python3.12/site-packages/sqlalchemy/pool/impl.py", line 179, in _do_get
    with util.safe_reraise():
  File "/home/hk/.local/lib/python3.12/site-packages/sqlalchemy/util/langhelpers.py", line 146, in __exit__
    raise exc_value.with_traceback(exc_tb)
  File "/home/hk/.local/lib/python3.12/site-packages/sqlalchemy/pool/impl.py", line 177, in _do_get
    return self._create_connection()
           ^^^^^^^^^^^^^^^^^^^^^^^^^
  File "/home/hk/.local/lib/python3.12/site-packages/sqlalchemy/pool/base.py", line 390, in _create_connection
    return _ConnectionRecord(self)
           ^^^^^^^^^^^^^^^^^^^^^^^
  File "/home/hk/.local/lib/python3.12/site-packages/sqlalchemy/pool/base.py", line 674, in __init__
    self.__connect()
  File "/home/hk/.local/lib/python3.12/site-packages/sqlalchemy/pool/base.py", line 900, in __connect
    with util.safe_reraise():
  File "/home/hk/.local/lib/python3.12/site-packages/sqlalchemy/util/langhelpers.py", line 146, in __exit__
    raise exc_value.with_traceback(exc_tb)
  File "/home/hk/.local/lib/python3.12/site-packages/sqlalchemy/pool/base.py", line 896, in __connect
    self.dbapi_connection = connection = pool._invoke_creator(self)
                                         ^^^^^^^^^^^^^^^^^^^^^^^^^^
  File "/home/hk/.local/lib/python3.12/site-packages/sqlalchemy/engine/create.py", line 643, in connect
    return dialect.connect(*cargs, **cparams)
           ^^^^^^^^^^^^^^^^^^^^^^^^^^^^^^^^^^
  File "/home/hk/.local/lib/python3.12/site-packages/sqlalchemy/engine/default.py", line 620, in connect
    return self.loaded_dbapi.connect(*cargs, **cparams)
           ^^^^^^^^^^^^^^^^^^^^^^^^^^^^^^^^^^^^^^^^^^^^
  File "/usr/local/lib/python3.12/dist-packages/MySQLdb/__init__.py", line 121, in Connect
    return Connection(*args, **kwargs)
           ^^^^^^^^^^^^^^^^^^^^^^^^^^^
  File "/usr/local/lib/python3.12/dist-packages/MySQLdb/connections.py", line 195, in __init__
    super().__init__(*args, **kwargs2)
MySQLdb.OperationalError: (2002, "Can't connect to local MySQL server through socket '/var/run/mysqld/mysqld.sock' (2)")

The above exception was the direct cause of the following exception:

Traceback (most recent call last):
  File "/usr/lib/python3/dist-packages/gunicorn/arbiter.py", line 589, in spawn_worker
    worker.init_process()
  File "/usr/lib/python3/dist-packages/gunicorn/workers/base.py", line 134, in init_process
    self.load_wsgi()
  File "/usr/lib/python3/dist-packages/gunicorn/workers/base.py", line 146, in load_wsgi
    self.wsgi = self.app.wsgi()
                ^^^^^^^^^^^^^^^
  File "/usr/lib/python3/dist-packages/gunicorn/app/base.py", line 67, in wsgi
    self.callable = self.load()
                    ^^^^^^^^^^^
  File "/usr/lib/python3/dist-packages/gunicorn/app/wsgiapp.py", line 58, in load
    return self.load_wsgiapp()
           ^^^^^^^^^^^^^^^^^^^
  File "/usr/lib/python3/dist-packages/gunicorn/app/wsgiapp.py", line 48, in load_wsgiapp
    return util.import_app(self.app_uri)
           ^^^^^^^^^^^^^^^^^^^^^^^^^^^^^
  File "/usr/lib/python3/dist-packages/gunicorn/util.py", line 384, in import_app
    mod = importlib.import_module(module)
          ^^^^^^^^^^^^^^^^^^^^^^^^^^^^^^^
  File "/usr/lib/python3.12/importlib/__init__.py", line 90, in import_module
    return _bootstrap._gcd_import(name[level:], package, level)
           ^^^^^^^^^^^^^^^^^^^^^^^^^^^^^^^^^^^^^^^^^^^^^^^^^^^^
  File "<frozen importlib._bootstrap>", line 1387, in _gcd_import
  File "<frozen importlib._bootstrap>", line 1360, in _find_and_load
  File "<frozen importlib._bootstrap>", line 1331, in _find_and_load_unlocked
  File "<frozen importlib._bootstrap>", line 935, in _load_unlocked
  File "<frozen importlib._bootstrap_external>", line 995, in exec_module
  File "<frozen importlib._bootstrap>", line 488, in _call_with_frames_removed
  File "/home/hk/grocree/webapp/v1/app.py", line 3, in <module>
    from models import Customer, Order, Orderline, Grocery
  File "/home/hk/grocree/models/__init__.py", line 6, in <module>
    storage.reload()
  File "/home/hk/grocree/models/storage/db_storage.py", line 48, in reload
    base.metadata.create_all(self.__engine)
  File "/home/hk/.local/lib/python3.12/site-packages/sqlalchemy/sql/schema.py", line 5857, in create_all
    bind._run_ddl_visitor(
  File "/home/hk/.local/lib/python3.12/site-packages/sqlalchemy/engine/base.py", line 3250, in _run_ddl_visitor
    with self.begin() as conn:
  File "/usr/lib/python3.12/contextlib.py", line 137, in __enter__
    return next(self.gen)
           ^^^^^^^^^^^^^^
  File "/home/hk/.local/lib/python3.12/site-packages/sqlalchemy/engine/base.py", line 3240, in begin
    with self.connect() as conn:
         ^^^^^^^^^^^^^^
  File "/home/hk/.local/lib/python3.12/site-packages/sqlalchemy/engine/base.py", line 3276, in connect
    return self._connection_cls(self)
           ^^^^^^^^^^^^^^^^^^^^^^^^^^
  File "/home/hk/.local/lib/python3.12/site-packages/sqlalchemy/engine/base.py", line 148, in __init__
    Connection._handle_dbapi_exception_noconnection(
  File "/home/hk/.local/lib/python3.12/site-packages/sqlalchemy/engine/base.py", line 2440, in _handle_dbapi_exception_noconnection
    raise sqlalchemy_exception.with_traceback(exc_info[2]) from e
  File "/home/hk/.local/lib/python3.12/site-packages/sqlalchemy/engine/base.py", line 146, in __init__
    self._dbapi_connection = engine.raw_connection()
                             ^^^^^^^^^^^^^^^^^^^^^^^
  File "/home/hk/.local/lib/python3.12/site-packages/sqlalchemy/engine/base.py", line 3300, in raw_connection
    return self.pool.connect()
           ^^^^^^^^^^^^^^^^^^^
  File "/home/hk/.local/lib/python3.12/site-packages/sqlalchemy/pool/base.py", line 449, in connect
    return _ConnectionFairy._checkout(self)
           ^^^^^^^^^^^^^^^^^^^^^^^^^^^^^^^^
  File "/home/hk/.local/lib/python3.12/site-packages/sqlalchemy/pool/base.py", line 1263, in _checkout
    fairy = _ConnectionRecord.checkout(pool)
            ^^^^^^^^^^^^^^^^^^^^^^^^^^^^^^^^
  File "/home/hk/.local/lib/python3.12/site-packages/sqlalchemy/pool/base.py", line 712, in checkout
    rec = pool._do_get()
          ^^^^^^^^^^^^^^
  File "/home/hk/.local/lib/python3.12/site-packages/sqlalchemy/pool/impl.py", line 179, in _do_get
    with util.safe_reraise():
  File "/home/hk/.local/lib/python3.12/site-packages/sqlalchemy/util/langhelpers.py", line 146, in __exit__
    raise exc_value.with_traceback(exc_tb)
  File "/home/hk/.local/lib/python3.12/site-packages/sqlalchemy/pool/impl.py", line 177, in _do_get
    return self._create_connection()
           ^^^^^^^^^^^^^^^^^^^^^^^^^
  File "/home/hk/.local/lib/python3.12/site-packages/sqlalchemy/pool/base.py", line 390, in _create_connection
    return _ConnectionRecord(self)
           ^^^^^^^^^^^^^^^^^^^^^^^
  File "/home/hk/.local/lib/python3.12/site-packages/sqlalchemy/pool/base.py", line 674, in __init__
    self.__connect()
  File "/home/hk/.local/lib/python3.12/site-packages/sqlalchemy/pool/base.py", line 900, in __connect
    with util.safe_reraise():
  File "/home/hk/.local/lib/python3.12/site-packages/sqlalchemy/util/langhelpers.py", line 146, in __exit__
    raise exc_value.with_traceback(exc_tb)
  File "/home/hk/.local/lib/python3.12/site-packages/sqlalchemy/pool/base.py", line 896, in __connect
    self.dbapi_connection = connection = pool._invoke_creator(self)
                                         ^^^^^^^^^^^^^^^^^^^^^^^^^^
  File "/home/hk/.local/lib/python3.12/site-packages/sqlalchemy/engine/create.py", line 643, in connect
    return dialect.connect(*cargs, **cparams)
           ^^^^^^^^^^^^^^^^^^^^^^^^^^^^^^^^^^
  File "/home/hk/.local/lib/python3.12/site-packages/sqlalchemy/engine/default.py", line 620, in connect
    return self.loaded_dbapi.connect(*cargs, **cparams)
           ^^^^^^^^^^^^^^^^^^^^^^^^^^^^^^^^^^^^^^^^^^^^
  File "/usr/local/lib/python3.12/dist-packages/MySQLdb/__init__.py", line 121, in Connect
    return Connection(*args, **kwargs)
           ^^^^^^^^^^^^^^^^^^^^^^^^^^^
  File "/usr/local/lib/python3.12/dist-packages/MySQLdb/connections.py", line 195, in __init__
    super().__init__(*args, **kwargs2)
sqlalchemy.exc.OperationalError: (MySQLdb.OperationalError) (2002, "Can't connect to local MySQL server through socket '/var/run/mysqld/mysqld.sock' (2)")
(Background on this error at: https://sqlalche.me/e/20/e3q8)
[2024-06-28 13:52:35 +0300] [2717] [INFO] Worker exiting (pid: 2717)
[2024-06-28 13:52:35 +0300] [2716] [INFO] Worker exiting (pid: 2716)
[2024-06-28 13:52:35 +0300] [2568] [WARNING] Worker with pid 2716 was terminated due to signal 15
[2024-06-28 13:52:35 +0300] [2568] [WARNING] Worker with pid 2717 was terminated due to signal 15
[2024-06-28 13:52:35 +0300] [2568] [INFO] Shutting down: Master
[2024-06-28 13:52:35 +0300] [2568] [INFO] Reason: Worker failed to boot.
[2024-06-28 13:54:45 +0300] [4859] [INFO] Starting gunicorn 20.1.0
[2024-06-28 13:54:45 +0300] [4859] [INFO] Listening at: http://127.0.0.1:8080 (4859)
[2024-06-28 13:54:45 +0300] [4859] [INFO] Using worker: sync
[2024-06-28 13:54:45 +0300] [4860] [INFO] Booting worker with pid: 4860
[2024-06-28 13:54:45 +0300] [4861] [INFO] Booting worker with pid: 4861
[2024-06-28 13:54:45 +0300] [4862] [INFO] Booting worker with pid: 4862
[2024-06-28 14:04:55 +0300] [4859] [INFO] Handling signal: term
[2024-06-28 14:04:55 +0300] [4861] [INFO] Worker exiting (pid: 4861)
[2024-06-28 14:04:55 +0300] [4860] [INFO] Worker exiting (pid: 4860)
[2024-06-28 14:04:55 +0300] [4862] [INFO] Worker exiting (pid: 4862)
[2024-06-28 14:04:55 +0300] [4859] [INFO] Shutting down: Master
[2024-06-28 14:06:42 +0300] [2572] [INFO] Starting gunicorn 20.1.0
[2024-06-28 14:06:42 +0300] [2572] [INFO] Listening at: http://127.0.0.1:8080 (2572)
[2024-06-28 14:06:42 +0300] [2572] [INFO] Using worker: sync
[2024-06-28 14:06:42 +0300] [2754] [INFO] Booting worker with pid: 2754
[2024-06-28 14:06:43 +0300] [2755] [INFO] Booting worker with pid: 2755
[2024-06-28 14:06:43 +0300] [2756] [INFO] Booting worker with pid: 2756
